<sdf version='1.6'>
  <world name='default'>
    <gui fullscreen='0'>
      <camera name='user_camera'>
        <pose frame=''>0.044104 -25.4243 6.3133 0 0.26 1.392</pose>
        <view_controller>orbit</view_controller>
        <projection_type>perspective</projection_type>
      </camera>
    </gui>
    <physics name='default_physics' default='0' type='ode'>
      <real_time_factor>1</real_time_factor>
      <real_time_update_rate>0</real_time_update_rate>
      <max_step_size>0.002</max_step_size>
    </physics>
    <scene>
      <ambient>0.7 0.7 0.7 1</ambient>
      <background>0.1 0.1 0.1 1</background>
      <shadows>1</shadows>
    </scene>
    <light name='sun' type='directional'>
      <cast_shadows>1</cast_shadows>
      <pose frame=''>0 0 10 0 -0 0</pose>
      <diffuse>0.8 0.8 0.8 1</diffuse>
      <specular>0.2 0.2 0.2 1</specular>
      <attenuation>
        <range>1000</range>
        <constant>0.9</constant>
        <linear>0.01</linear>
        <quadratic>0.001</quadratic>
      </attenuation>
      <direction>-0.5 0.1 -0.9</direction>
    </light>
    <model name='ground_plane'>
      <static>1</static>
      <link name='link'>
        <collision name='collision'>
          <geometry>
            <plane>
              <normal>0 0 1</normal>
              <size>100 100</size>
            </plane>
          </geometry>
          <surface>
            <contact>
              <collide_bitmask>65535</collide_bitmask>
              <ode/>
            </contact>
            <friction>
              <ode>
                <mu>100</mu>
                <mu2>50</mu2>
              </ode>
              <torsional>
                <ode/>
              </torsional>
            </friction>
            <bounce/>
          </surface>
          <max_contacts>10</max_contacts>
        </collision>
        <visual name='visual'>
          <cast_shadows>0</cast_shadows>
          <geometry>
            <plane>
              <normal>0 0 1</normal>
              <size>100 100</size>
            </plane>
          </geometry>
          <material>
            <script>
              <uri>file://media/materials/scripts/gazebo.material</uri>
              <name>Gazebo/Grey</name>
            </script>
          </material>
        </visual>
        <self_collide>0</self_collide>
        <enable_wind>0</enable_wind>
        <kinematic>0</kinematic>
      </link>
    </model>
    <gravity>0 0 -9.8</gravity>
    <magnetic_field>6e-06 2.3e-05 -4.2e-05</magnetic_field>
    <atmosphere type='adiabatic'/>
    <wind/>
    <spherical_coordinates>
      <surface_model>EARTH_WGS84</surface_model>
      <latitude_deg>0</latitude_deg>
      <longitude_deg>0</longitude_deg>
      <elevation>0</elevation>
      <heading_deg>0</heading_deg>
    </spherical_coordinates>
    <model name='seed_r7'>
      <link name='base_link'>
        <pose frame=''>0 0 0 0 -0 0</pose>
        <inertial>
          <pose frame=''>-0.000483 -0.000247 0.122246 0 -0 0</pose>
          <mass>82.846</mass>
          <inertia>
            <ixx>3.50606</ixx>
            <ixy>-0.000412149</ixy>
            <ixz>0.0130014</ixz>
            <iyy>12.4814</iyy>
            <iyz>0.00181134</iyz>
            <izz>14.5877</izz>
          </inertia>
        </inertial>
        <collision name='base_link_fixed_joint_lump__wheel_base_link_collision'>
          <pose frame=''>0.018 0 0.1125 0 -0 0</pose>
          <geometry>
            <box>
              <size>0.72 0.45 0.149</size>
            </box>
          </geometry>
          <surface>
            <contact>
              <ode/>
            </contact>
            <friction>
              <ode>
                <mu>0.9</mu>
                <mu2>0.9</mu2>
              </ode>
              <torsional>
                <ode/>
              </torsional>
            </friction>
            <bounce/>
          </surface>
          <max_contacts>10</max_contacts>
        </collision>
        <collision name='base_link_fixed_joint_lump__wheels_base_laser_link_collision_1'>
          <pose frame=''>0.29 0 0.195 0 -0 0</pose>
          <geometry>
            <box>
              <size>0.08 0.1 0.07</size>
            </box>
          </geometry>
          <surface>
            <contact>
              <ode/>
            </contact>
            <friction>
              <ode>
                <mu>0.9</mu>
                <mu2>0.9</mu2>
              </ode>
              <torsional>
                <ode/>
              </torsional>
            </friction>
            <bounce/>
          </surface>
          <max_contacts>10</max_contacts>
        </collision>
        <collision name='base_link_fixed_joint_lump__wheels_front_left_mecanum_collision_2'>
          <pose frame=''>0.2265 0.19485 0.075 -1.5708 0 0</pose>
          <geometry>
            <box>
              <size>0.152 0.152 0.046</size>
            </box>
          </geometry>
          <surface>
            <contact>
              <ode/>
            </contact>
            <friction>
              <ode>
                <mu>0.25</mu>
                <mu2>0.25</mu2>
              </ode>
              <torsional>
                <ode/>
              </torsional>
            </friction>
            <bounce/>
          </surface>
          <max_contacts>10</max_contacts>
        </collision>
        <collision name='base_link_fixed_joint_lump__wheels_front_right_mecanum_collision_3'>
          <pose frame=''>0.2265 -0.19485 0.075 -1.5708 0 0</pose>
          <geometry>
            <box>
              <size>0.152 0.152 0.046</size>
            </box>
          </geometry>
          <max_contacts>10</max_contacts>
          <surface>
            <contact>
              <ode/>
            </contact>
            <bounce/>
            <friction>
              <torsional>
                <ode/>
              </torsional>
              <ode/>
            </friction>
          </surface>
        </collision>
        <collision name='base_link_fixed_joint_lump__wheels_rear_left_mecanum_collision_4'>
          <pose frame=''>-0.2265 0.19485 0.075 -1.5708 0 0</pose>
          <geometry>
            <box>
              <size>0.152 0.152 0.046</size>
            </box>
          </geometry>
          <surface>
            <contact>
              <ode/>
            </contact>
            <friction>
              <ode>
                <mu>0.25</mu>
                <mu2>0.25</mu2>
              </ode>
              <torsional>
                <ode/>
              </torsional>
            </friction>
            <bounce/>
          </surface>
          <max_contacts>10</max_contacts>
        </collision>
        <collision name='base_link_fixed_joint_lump__wheels_rear_right_mecanum_collision_5'>
          <pose frame=''>-0.2265 -0.19485 0.075 -1.5708 0 0</pose>
          <geometry>
            <box>
              <size>0.152 0.152 0.046</size>
            </box>
          </geometry>
          <surface>
            <contact>
              <ode/>
            </contact>
            <friction>
              <ode>
                <mu>0.25</mu>
                <mu2>0.25</mu2>
              </ode>
              <torsional>
                <ode/>
              </torsional>
            </friction>
            <bounce/>
          </surface>
          <max_contacts>10</max_contacts>
        </collision>
        <collision name='base_link_fixed_joint_lump__lifter_base_link_collision_6'>
          <pose frame=''>0 0 0.255 0 -0 0</pose>
          <geometry>
            <box>
              <size>0.08 0.1 0.1</size>
            </box>
          </geometry>
          <surface>
            <contact>
              <ode/>
            </contact>
            <friction>
              <ode>
                <mu>0.9</mu>
                <mu2>0.9</mu2>
              </ode>
              <torsional>
                <ode/>
              </torsional>
            </friction>
            <bounce/>
          </surface>
          <max_contacts>10</max_contacts>
        </collision>
        <collision name='base_link_fixed_joint_lump__lifter_base_link_collision_7'>
          <pose frame=''>0 0 0.2 0 -0 0</pose>
          <geometry>
            <box>
              <size>0.08 0.16 0.01</size>
            </box>
          </geometry>
          <surface>
            <contact>
              <ode/>
            </contact>
            <friction>
              <ode>
                <mu>0.9</mu>
                <mu2>0.9</mu2>
              </ode>
              <torsional>
                <ode/>
              </torsional>
            </friction>
            <bounce/>
          </surface>
          <max_contacts>10</max_contacts>
        </collision>
        <visual name='base_link_fixed_joint_lump__wheel_base_link_visual'>
          <pose frame=''>0 0 0.075 0 -0 0</pose>
          <geometry>
            <mesh>
              <scale>1 1 1</scale>
              <uri>/home/ubuntu18/ros/melodic/src/seed_r7_ros_pkg/seed_r7_description/meshes/typeE_wheel/wheels_base.dae</uri>
            </mesh>
          </geometry>
          <material>
            <script>
              <uri>__default__</uri>
              <name>__default__</name>
            </script>
          </material>
        </visual>
        <visual name='base_link_fixed_joint_lump__wheels_base_laser_link_visual_1'>
          <pose frame=''>0.29 0 0.2074 0 -0 0</pose>
          <geometry>
            <mesh>
              <scale>1 1 1</scale>
              <uri>/home/ubuntu18/ros/melodic/src/seed_r7_ros_pkg/seed_r7_description/meshes/typeE_wheel/wheels_urg.dae</uri>
            </mesh>
          </geometry>
          <material>
            <script>
              <uri>__default__</uri>
              <name>__default__</name>
            </script>
          </material>
        </visual>
        <visual name='base_link_fixed_joint_lump__wheels_front_left_mecanum_visual_2'>
          <pose frame=''>0.2265 0.19485 0.075 -1.5708 0 0</pose>
          <geometry>
            <mesh>
              <scale>1 1 1</scale>
              <uri>/home/ubuntu18/ros/melodic/src/seed_r7_ros_pkg/seed_r7_description/meshes/typeE_wheel/wheels_mecanum.dae</uri>
            </mesh>
          </geometry>
          <material>
            <script>
              <uri>__default__</uri>
              <name>__default__</name>
            </script>
          </material>
        </visual>
        <visual name='base_link_fixed_joint_lump__wheels_front_right_mecanum_visual_3'>
          <pose frame=''>0.2265 -0.19485 0.075 -1.5708 0 0</pose>
          <geometry>
            <mesh>
              <scale>1 1 1</scale>
              <uri>/home/ubuntu18/ros/melodic/src/seed_r7_ros_pkg/seed_r7_description/meshes/typeE_wheel/wheels_mecanum.dae</uri>
            </mesh>
          </geometry>
        </visual>
        <visual name='base_link_fixed_joint_lump__wheels_rear_left_mecanum_visual_4'>
          <pose frame=''>-0.2265 0.19485 0.075 -1.5708 0 0</pose>
          <geometry>
            <mesh>
              <scale>1 1 1</scale>
              <uri>/home/ubuntu18/ros/melodic/src/seed_r7_ros_pkg/seed_r7_description/meshes/typeE_wheel/wheels_mecanum.dae</uri>
            </mesh>
          </geometry>
          <material>
            <script>
              <uri>__default__</uri>
              <name>__default__</name>
            </script>
          </material>
        </visual>
        <visual name='base_link_fixed_joint_lump__wheels_rear_right_mecanum_visual_5'>
          <pose frame=''>-0.2265 -0.19485 0.075 -1.5708 0 0</pose>
          <geometry>
            <mesh>
              <scale>1 1 1</scale>
              <uri>/home/ubuntu18/ros/melodic/src/seed_r7_ros_pkg/seed_r7_description/meshes/typeE_wheel/wheels_mecanum.dae</uri>
            </mesh>
          </geometry>
          <material>
            <script>
              <uri>__default__</uri>
              <name>__default__</name>
            </script>
          </material>
        </visual>
        <visual name='base_link_fixed_joint_lump__wheels_top_link_visual_6'>
          <pose frame=''>0 0 0.19 0 -0 0</pose>
          <geometry>
            <mesh>
              <scale>1 1 1</scale>
              <uri>/home/ubuntu18/ros/melodic/src/seed_r7_ros_pkg/seed_r7_description/meshes/typeE_wheel/wheels_top.dae</uri>
            </mesh>
          </geometry>
          <material>
            <script>
              <uri>__default__</uri>
              <name>__default__</name>
            </script>
          </material>
        </visual>
        <visual name='base_link_fixed_joint_lump__lifter_base_link_visual_7'>
          <pose frame=''>0 0 0.195 0 -0 0</pose>
          <geometry>
            <mesh>
              <scale>1 1 1</scale>
              <uri>/home/ubuntu18/ros/melodic/src/seed_r7_ros_pkg/seed_r7_description/meshes/typeC_lifter/lifter_base.dae</uri>
            </mesh>
          </geometry>
          <material>
            <script>
              <uri>__default__</uri>
              <name>__default__</name>
            </script>
          </material>
        </visual>
        <velocity_decay/>
        <velocity_decay/>
        <velocity_decay/>
        <sensor name='head_hokuyo_sensor' type='ray'>
          <visualize>0</visualize>
          <update_rate>10</update_rate>
          <ray>
            <scan>
              <horizontal>
                <samples>1000</samples>
                <resolution>1</resolution>
                <min_angle>-2.35619</min_angle>
                <max_angle>2.35619</max_angle>
              </horizontal>
              <vertical>
                <samples>1</samples>
                <min_angle>0</min_angle>
                <max_angle>0</max_angle>
              </vertical>
            </scan>
            <range>
              <min>0.08</min>
              <max>20</max>
              <resolution>0.01</resolution>
            </range>
            <noise>
              <type>gaussian</type>
              <mean>0</mean>
              <stddev>0.01</stddev>
            </noise>
          </ray>
          <plugin name='gazebo_ros_head_hokuyo_controller' filename='libgazebo_ros_laser.so'>
            <topicName>scan</topicName>
            <frameName>wheels_base_laser_link</frameName>
            <robotNamespace>/</robotNamespace>
          </plugin>
          <pose frame=''>0.29 0 0.2074 0 -0 0</pose>
        </sensor>
        <velocity_decay/>
        <velocity_decay/>
        <velocity_decay/>
        <velocity_decay/>
        <velocity_decay/>
        <gravity>1</gravity>
        <velocity_decay/>
        <self_collide>0</self_collide>
        <enable_wind>0</enable_wind>
        <kinematic>0</kinematic>
      </link>
      <link name='leg_shank_link'>
        <pose frame=''>0 0 0.245 0 -0 0</pose>
        <inertial>
          <pose frame=''>0.051713 0 0.146934 0 -0 0</pose>
          <mass>2.06679</mass>
          <inertia>
            <ixx>0.06</ixx>
            <ixy>0</ixy>
            <ixz>0</ixz>
            <iyy>0.1</iyy>
            <iyz>0</iyz>
            <izz>0.06</izz>
          </inertia>
        </inertial>
        <collision name='leg_shank_link_collision'>
          <pose frame=''>0 0 0.13 0 -0 0</pose>
          <geometry>
            <box>
              <size>0.07 0.1 0.325</size>
            </box>
          </geometry>
          <surface>
            <contact>
              <ode/>
            </contact>
            <friction>
              <ode>
                <mu>0.9</mu>
                <mu2>0.9</mu2>
              </ode>
              <torsional>
                <ode/>
              </torsional>
            </friction>
            <bounce/>
          </surface>
          <max_contacts>10</max_contacts>
        </collision>
        <visual name='leg_shank_link_visual'>
          <pose frame=''>0 0 0 3.1415 -0 0</pose>
          <geometry>
            <mesh>
              <scale>1 1 1</scale>
              <uri>/home/ubuntu18/ros/melodic/src/seed_r7_ros_pkg/seed_r7_description/meshes/typeC_lifter/lifter_bone.dae</uri>
            </mesh>
          </geometry>
          <material>
            <script>
              <uri>__default__</uri>
              <name>__default__</name>
            </script>
          </material>
        </visual>
        <gravity>1</gravity>
        <velocity_decay/>
        <self_collide>0</self_collide>
        <enable_wind>0</enable_wind>
        <kinematic>0</kinematic>
      </link>
      <joint name='ankle_joint' type='revolute'>
        <child>leg_shank_link</child>
        <parent>base_link</parent>
        <axis>
          <xyz>0 -1 0</xyz>
          <limit>
            <lower>0</lower>
            <upper>1.5707</upper>
            <effort>200</effort>
            <velocity>0.5</velocity>
          </limit>
          <dynamics>
            <damping>0.2</damping>
            <friction>0</friction>
            <spring_reference>0</spring_reference>
            <spring_stiffness>0</spring_stiffness>
          </dynamics>
          <use_parent_model_frame>1</use_parent_model_frame>
        </axis>
        <physics>
          <ode>
            <implicit_spring_damper>0</implicit_spring_damper>
            <cfm_damping>0</cfm_damping>
            <limit>
              <cfm>0</cfm>
              <erp>0.2</erp>
            </limit>
          </ode>
        </physics>
      </joint>
      <link name='leg_knee_link'>
        <pose frame=''>0 0 0.495 0 -0 0</pose>
        <inertial>
          <pose frame=''>-0.031713 0 0.046934 0 -0 0</pose>
          <mass>2.06679</mass>
          <inertia>
            <ixx>0.06</ixx>
            <ixy>0</ixy>
            <ixz>0</ixz>
            <iyy>0.1</iyy>
            <iyz>0</iyz>
            <izz>0.06</izz>
          </inertia>
        </inertial>
        <collision name='leg_knee_link_collision'>
          <pose frame=''>0 0 0.06 0 -0 0</pose>
          <geometry>
            <box>
              <size>0.09 0.09 0.2</size>
            </box>
          </geometry>
          <surface>
            <contact>
              <ode/>
            </contact>
            <friction>
              <ode>
                <mu>0.9</mu>
                <mu2>0.9</mu2>
              </ode>
              <torsional>
                <ode/>
              </torsional>
            </friction>
            <bounce/>
          </surface>
          <max_contacts>10</max_contacts>
        </collision>
        <visual name='leg_knee_link_visual'>
          <pose frame=''>0 0 0 3.1415 -0 0</pose>
          <geometry>
            <mesh>
              <scale>1 1 1</scale>
              <uri>/home/ubuntu18/ros/melodic/src/seed_r7_ros_pkg/seed_r7_description/meshes/typeC_lifter/lifter_knee.dae</uri>
            </mesh>
          </geometry>
          <material>
            <script>
              <uri>__default__</uri>
              <name>__default__</name>
            </script>
          </material>
        </visual>
        <gravity>1</gravity>
        <velocity_decay/>
        <self_collide>0</self_collide>
        <enable_wind>0</enable_wind>
        <kinematic>0</kinematic>
      </link>
      <joint name='ankle_joint_mimic' type='revolute'>
        <child>leg_knee_link</child>
        <parent>leg_shank_link</parent>
        <axis>
          <xyz>0 -1 0</xyz>
          <limit>
            <lower>-1e+16</lower>
            <upper>1e+16</upper>
          </limit>
          <dynamics>
            <spring_reference>0</spring_reference>
            <spring_stiffness>0</spring_stiffness>
          </dynamics>
          <use_parent_model_frame>1</use_parent_model_frame>
        </axis>
      </joint>
      <link name='leg_thigh_link'>
        <pose frame=''>0 0 0.615 0 -0 0</pose>
        <inertial>
          <pose frame=''>-0.058717 0 0.135292 0 -0 0</pose>
          <mass>2.62321</mass>
          <inertia>
            <ixx>0.0161595</ixx>
            <ixy>-9.27234e-05</ixy>
            <ixz>0.00262839</ixz>
            <iyy>0.0166415</iyy>
            <iyz>-0.00017447</iyz>
            <izz>0.00477281</izz>
          </inertia>
        </inertial>
        <collision name='leg_thigh_link_collision'>
          <pose frame=''>0 0 0.12 0 -0 0</pose>
          <geometry>
            <box>
              <size>0.07 0.1 0.325</size>
            </box>
          </geometry>
          <surface>
            <contact>
              <ode/>
            </contact>
            <friction>
              <ode>
                <mu>0.9</mu>
                <mu2>0.9</mu2>
              </ode>
              <torsional>
                <ode/>
              </torsional>
            </friction>
            <bounce/>
          </surface>
          <max_contacts>10</max_contacts>
        </collision>
        <visual name='leg_thigh_link_visual'>
          <pose frame=''>0 0 0.25 0 -0 0</pose>
          <geometry>
            <mesh>
              <scale>1 1 1</scale>
              <uri>/home/ubuntu18/ros/melodic/src/seed_r7_ros_pkg/seed_r7_description/meshes/typeC_lifter/lifter_bone.dae</uri>
            </mesh>
          </geometry>
          <material>
            <script>
              <uri>__default__</uri>
              <name>__default__</name>
            </script>
          </material>
        </visual>
        <gravity>1</gravity>
        <velocity_decay/>
        <self_collide>0</self_collide>
        <enable_wind>0</enable_wind>
        <kinematic>0</kinematic>
      </link>
      <joint name='knee_joint' type='revolute'>
        <child>leg_thigh_link</child>
        <parent>leg_knee_link</parent>
        <axis>
          <xyz>0 -1 0</xyz>
          <limit>
            <lower>-1.5707</lower>
            <upper>0</upper>
            <effort>200</effort>
            <velocity>0.5</velocity>
          </limit>
          <dynamics>
            <damping>0.2</damping>
            <friction>0</friction>
            <spring_reference>0</spring_reference>
            <spring_stiffness>0</spring_stiffness>
          </dynamics>
          <use_parent_model_frame>1</use_parent_model_frame>
        </axis>
        <physics>
          <ode>
            <implicit_spring_damper>0</implicit_spring_damper>
            <cfm_damping>0</cfm_damping>
            <limit>
              <cfm>0</cfm>
              <erp>0.2</erp>
            </limit>
          </ode>
        </physics>
      </joint>
      <link name='leg_base_link'>
        <pose frame=''>0 0 0.865 0 -0 0</pose>
        <inertial>
          <pose frame=''>-0.009897 -0.002068 0.0181 0 -0 0</pose>
          <mass>9.90304</mass>
          <inertia>
            <ixx>0.133807</ixx>
            <ixy>-0.000219307</ixy>
            <ixz>0.00903538</ixz>
            <iyy>0.118694</iyy>
            <iyz>-4.9684e-05</iyz>
            <izz>0.147276</izz>
          </inertia>
        </inertial>
        <collision name='leg_base_link_collision'>
          <pose frame=''>0 0 0 0 -0 0</pose>
          <geometry>
            <box>
              <size>0.08 0.1 0.1</size>
            </box>
          </geometry>
          <surface>
            <contact>
              <ode/>
            </contact>
            <friction>
              <ode>
                <mu>0.9</mu>
                <mu2>0.9</mu2>
              </ode>
              <torsional>
                <ode/>
              </torsional>
            </friction>
            <bounce/>
          </surface>
          <max_contacts>10</max_contacts>
        </collision>
        <collision name='leg_base_link_collision_1'>
          <pose frame=''>0 0 0.045 0 -0 0</pose>
          <geometry>
            <box>
              <size>0.08 0.16 0.01</size>
            </box>
          </geometry>
          <surface>
            <contact>
              <ode/>
            </contact>
            <friction>
              <ode>
                <mu>0.9</mu>
                <mu2>0.9</mu2>
              </ode>
              <torsional>
                <ode/>
              </torsional>
            </friction>
            <bounce/>
          </surface>
          <max_contacts>10</max_contacts>
        </collision>
        <collision name='leg_base_link_fixed_joint_lump__lifter_top_link_collision_2'>
          <pose frame=''>0 0 0.055 0 -0 0</pose>
          <geometry>
            <box>
              <size>0.16 0.24 0.01</size>
            </box>
          </geometry>
          <surface>
            <contact>
              <ode/>
            </contact>
            <friction>
              <ode>
                <mu>0.9</mu>
                <mu2>0.9</mu2>
              </ode>
              <torsional>
                <ode/>
              </torsional>
            </friction>
            <bounce/>
          </surface>
          <max_contacts>10</max_contacts>
        </collision>
        <visual name='leg_base_link_visual'>
          <pose frame=''>0 0 0.05 3.14159 -0 0</pose>
          <geometry>
            <mesh>
              <scale>1 1 1</scale>
              <uri>/home/ubuntu18/ros/melodic/src/seed_r7_ros_pkg/seed_r7_description/meshes/typeC_lifter/lifter_base.dae</uri>
            </mesh>
          </geometry>
          <material>
            <script>
              <uri>__default__</uri>
              <name>__default__</name>
            </script>
          </material>
        </visual>
        <visual name='leg_base_link_fixed_joint_lump__lifter_top_link_visual_1'>
          <pose frame=''>0 0 0.055 0 -0 0</pose>
          <geometry>
            <mesh>
              <scale>1 1 1</scale>
              <uri>/home/ubuntu18/ros/melodic/src/seed_r7_ros_pkg/seed_r7_description/meshes/typeC_lifter/lifter_top.dae</uri>
            </mesh>
          </geometry>
          <material>
            <script>
              <uri>__default__</uri>
              <name>__default__</name>
            </script>
          </material>
        </visual>
        <velocity_decay/>
        <velocity_decay/>
        <gravity>1</gravity>
        <velocity_decay/>
        <self_collide>0</self_collide>
        <enable_wind>0</enable_wind>
        <kinematic>0</kinematic>
      </link>
      <joint name='knee_joint_mimic' type='revolute'>
        <child>leg_base_link</child>
        <parent>leg_thigh_link</parent>
        <axis>
          <xyz>0 -1 0</xyz>
          <limit>
            <lower>-1e+16</lower>
            <upper>1e+16</upper>
          </limit>
          <dynamics>
            <spring_reference>0</spring_reference>
            <spring_stiffness>0</spring_stiffness>
          </dynamics>
          <use_parent_model_frame>1</use_parent_model_frame>
        </axis>
      </joint>
      <link name='hip_sphere_link'>
        <pose frame=''>0 0 0.93 0 -0 0</pose>
        <inertial>
          <pose frame=''>0 0 0.042 0 -0 0</pose>
          <mass>1.257</mass>
          <inertia>
            <ixx>0.01</ixx>
            <ixy>0</ixy>
            <ixz>0</ixz>
            <iyy>0.01</iyy>
            <iyz>0</iyz>
            <izz>0.007</izz>
          </inertia>
        </inertial>
        <collision name='hip_sphere_link_collision'>
          <pose frame=''>0 0 0.04 0 -0 0</pose>
          <geometry>
            <cylinder>
              <length>0.09</length>
              <radius>0.06</radius>
            </cylinder>
          </geometry>
          <surface>
            <contact>
              <ode/>
            </contact>
            <friction>
              <ode>
                <mu>0.9</mu>
                <mu2>0.9</mu2>
              </ode>
              <torsional>
                <ode/>
              </torsional>
            </friction>
            <bounce/>
          </surface>
          <max_contacts>10</max_contacts>
        </collision>
        <collision name='hip_sphere_link_collision_1'>
          <pose frame=''>0 0 0.12 0 -0 0</pose>
          <geometry>
            <sphere>
              <radius>0.078</radius>
            </sphere>
          </geometry>
          <surface>
            <contact>
              <ode/>
            </contact>
            <friction>
              <ode>
                <mu>0.9</mu>
                <mu2>0.9</mu2>
              </ode>
              <torsional>
                <ode/>
              </torsional>
            </friction>
            <bounce/>
          </surface>
          <max_contacts>10</max_contacts>
        </collision>
        <visual name='hip_sphere_link_visual'>
          <pose frame=''>0 0 0 0 -0 0</pose>
          <geometry>
            <mesh>
              <scale>1 1 1</scale>
              <uri>/home/ubuntu18/ros/melodic/src/seed_r7_ros_pkg/seed_r7_description/meshes/typeF_upperbody/WAIST_LINK1_mesh.dae</uri>
            </mesh>
          </geometry>
          <material>
            <script>
              <uri>__default__</uri>
              <name>__default__</name>
            </script>
          </material>
        </visual>
        <gravity>1</gravity>
        <velocity_decay/>
        <self_collide>0</self_collide>
        <enable_wind>0</enable_wind>
        <kinematic>0</kinematic>
      </link>
      <joint name='waist_y_joint' type='revolute'>
        <child>hip_sphere_link</child>
        <parent>leg_base_link</parent>
        <axis>
          <xyz>0 0 1</xyz>
          <limit>
            <lower>-2.09</lower>
            <upper>2.09</upper>
            <effort>10</effort>
            <velocity>0.6</velocity>
          </limit>
          <dynamics>
            <damping>0.2</damping>
            <friction>0</friction>
            <spring_reference>0</spring_reference>
            <spring_stiffness>0</spring_stiffness>
          </dynamics>
          <use_parent_model_frame>1</use_parent_model_frame>
        </axis>
        <physics>
          <ode>
            <implicit_spring_damper>0</implicit_spring_damper>
            <cfm_damping>0</cfm_damping>
            <limit>
              <cfm>0</cfm>
              <erp>0.2</erp>
            </limit>
          </ode>
        </physics>
      </joint>
      <link name='hip_center'>
        <pose frame=''>0 0 1.0655 0 -0 0</pose>
        <inertial>
          <pose frame=''>0 0 0 0 -0 0</pose>
          <mass>0.1</mass>
          <inertia>
            <ixx>0.003</ixx>
            <ixy>0</ixy>
            <ixz>0</ixz>
            <iyy>0.003</iyy>
            <iyz>0</iyz>
            <izz>0.003</izz>
          </inertia>
        </inertial>
        <gravity>1</gravity>
        <velocity_decay/>
        <self_collide>0</self_collide>
        <enable_wind>0</enable_wind>
        <kinematic>0</kinematic>
      </link>
      <joint name='waist_p_joint' type='revolute'>
        <child>hip_center</child>
        <parent>hip_sphere_link</parent>
        <axis>
          <xyz>0 1 0</xyz>
          <limit>
            <lower>-0.087</lower>
            <upper>0.61</upper>
            <effort>10</effort>
            <velocity>0.5</velocity>
          </limit>
          <dynamics>
            <damping>0.2</damping>
            <friction>0</friction>
            <spring_reference>0</spring_reference>
            <spring_stiffness>0</spring_stiffness>
          </dynamics>
          <use_parent_model_frame>1</use_parent_model_frame>
        </axis>
        <physics>
          <ode>
            <implicit_spring_damper>0</implicit_spring_damper>
            <cfm_damping>0</cfm_damping>
            <limit>
              <cfm>0</cfm>
              <erp>0.2</erp>
            </limit>
          </ode>
        </physics>
      </joint>
      <link name='body_link'>
        <pose frame=''>0 0 1.0655 0 -0 0</pose>
        <inertial>
          <pose frame=''>0 0 0.22 0 -0 0</pose>
          <mass>10.551</mass>
          <inertia>
            <ixx>0.13</ixx>
            <ixy>0</ixy>
            <ixz>0</ixz>
            <iyy>0.12</iyy>
            <iyz>0</iyz>
            <izz>0.114</izz>
          </inertia>
        </inertial>
        <collision name='body_link_collision'>
          <pose frame=''>0 0 0 0 -0 0</pose>
          <geometry>
            <mesh>
              <scale>1 1 1</scale>
              <uri>/home/ubuntu18/ros/melodic/src/seed_r7_ros_pkg/seed_r7_description/meshes/typeF_upperbody/WAIST_LINK3_mesh.dae</uri>
            </mesh>
          </geometry>
          <surface>
            <contact>
              <ode/>
            </contact>
            <friction>
              <ode>
                <mu>0.9</mu>
                <mu2>0.9</mu2>
              </ode>
              <torsional>
                <ode/>
              </torsional>
            </friction>
            <bounce/>
          </surface>
          <max_contacts>10</max_contacts>
        </collision>
        <visual name='body_link_visual'>
          <pose frame=''>0 0 0 0 -0 0</pose>
          <geometry>
            <mesh>
              <scale>1 1 1</scale>
              <uri>/home/ubuntu18/ros/melodic/src/seed_r7_ros_pkg/seed_r7_description/meshes/typeF_upperbody/WAIST_LINK3_mesh.dae</uri>
            </mesh>
          </geometry>
          <material>
            <script>
              <uri>__default__</uri>
              <name>__default__</name>
            </script>
          </material>
        </visual>
        <gravity>1</gravity>
        <velocity_decay/>
        <self_collide>0</self_collide>
        <enable_wind>0</enable_wind>
        <kinematic>0</kinematic>
      </link>
      <joint name='waist_r_joint' type='revolute'>
        <child>body_link</child>
        <parent>hip_center</parent>
        <axis>
          <xyz>1 0 0</xyz>
          <limit>
            <lower>-0.017</lower>
            <upper>0.017</upper>
            <effort>10</effort>
            <velocity>0.4</velocity>
          </limit>
          <dynamics>
            <damping>0.2</damping>
            <friction>0</friction>
            <spring_reference>0</spring_reference>
            <spring_stiffness>0</spring_stiffness>
          </dynamics>
          <use_parent_model_frame>1</use_parent_model_frame>
        </axis>
        <physics>
          <ode>
            <implicit_spring_damper>0</implicit_spring_damper>
            <cfm_damping>0</cfm_damping>
            <limit>
              <cfm>0</cfm>
              <erp>0.2</erp>
            </limit>
          </ode>
        </physics>
      </joint>
      <link name='l_shoulder_link'>
        <pose frame=''>-0.01815 0.1342 1.3704 0 -0 0</pose>
        <inertial>
          <pose frame=''>0 0.02 0.015 0 -0 0</pose>
          <mass>0.242</mass>
          <inertia>
            <ixx>0.00133</ixx>
            <ixy>0</ixy>
            <ixz>0</ixz>
            <iyy>0.001</iyy>
            <iyz>0</iyz>
            <izz>0.00133</izz>
          </inertia>
        </inertial>
        <collision name='l_shoulder_link_collision'>
          <pose frame=''>0 0 0 -0.174533 -0 0</pose>
          <geometry>
            <mesh>
              <scale>1 1 1</scale>
              <uri>/home/ubuntu18/ros/melodic/src/seed_r7_ros_pkg/seed_r7_description/meshes/typeF_upperbody/LARM_LINK1_mesh.dae</uri>
            </mesh>
          </geometry>
          <surface>
            <contact>
              <ode/>
            </contact>
            <friction>
              <ode>
                <mu>0.9</mu>
                <mu2>0.9</mu2>
              </ode>
              <torsional>
                <ode/>
              </torsional>
            </friction>
            <bounce/>
          </surface>
          <max_contacts>10</max_contacts>
        </collision>
        <visual name='l_shoulder_link_visual'>
          <pose frame=''>0 0 0 -0.174533 -0 0</pose>
          <geometry>
            <mesh>
              <scale>1 1 1</scale>
              <uri>/home/ubuntu18/ros/melodic/src/seed_r7_ros_pkg/seed_r7_description/meshes/typeF_upperbody/LARM_LINK1_mesh.dae</uri>
            </mesh>
          </geometry>
          <material>
            <script>
              <uri>__default__</uri>
              <name>__default__</name>
            </script>
          </material>
        </visual>
        <gravity>1</gravity>
        <velocity_decay/>
        <self_collide>0</self_collide>
        <enable_wind>0</enable_wind>
        <kinematic>0</kinematic>
      </link>
      <joint name='l_shoulder_p_joint' type='revolute'>
        <child>l_shoulder_link</child>
        <parent>body_link</parent>
        <axis>
          <xyz>0 0.984808 -0.173648</xyz>
          <limit>
            <lower>-1.535</lower>
            <upper>0.261</upper>
            <effort>10</effort>
            <velocity>0.4</velocity>
          </limit>
          <dynamics>
            <damping>0.2</damping>
            <friction>0</friction>
            <spring_reference>0</spring_reference>
            <spring_stiffness>0</spring_stiffness>
          </dynamics>
          <use_parent_model_frame>1</use_parent_model_frame>
        </axis>
        <physics>
          <ode>
            <implicit_spring_damper>0</implicit_spring_damper>
            <cfm_damping>0</cfm_damping>
            <limit>
              <cfm>0</cfm>
              <erp>0.2</erp>
            </limit>
          </ode>
        </physics>
      </joint>
      <link name='l_shoulder_center'>
        <pose frame=''>-0.01815 0.19398 1.39845 0 -0 0</pose>
        <inertial>
          <pose frame=''>0 -0.01 -0.06 0 -0 0</pose>
          <mass>0.744</mass>
          <inertia>
            <ixx>0.000841</ixx>
            <ixy>0</ixy>
            <ixz>0</ixz>
            <iyy>0.000835</iyy>
            <iyz>0</iyz>
            <izz>0.000304</izz>
          </inertia>
        </inertial>
        <collision name='l_shoulder_center_collision'>
          <pose frame=''>0 0 0 0 -0 0</pose>
          <geometry>
            <mesh>
              <scale>1 1 1</scale>
              <uri>/home/ubuntu18/ros/melodic/src/seed_r7_ros_pkg/seed_r7_description/meshes/typeF_upperbody/LARM_LINK2_mesh.dae</uri>
            </mesh>
          </geometry>
          <surface>
            <contact>
              <ode/>
            </contact>
            <friction>
              <ode>
                <mu>0.9</mu>
                <mu2>0.9</mu2>
              </ode>
              <torsional>
                <ode/>
              </torsional>
            </friction>
            <bounce/>
          </surface>
          <max_contacts>10</max_contacts>
        </collision>
        <visual name='l_shoulder_center_visual'>
          <pose frame=''>0 0 0 0 -0 0</pose>
          <geometry>
            <mesh>
              <scale>1 1 1</scale>
              <uri>/home/ubuntu18/ros/melodic/src/seed_r7_ros_pkg/seed_r7_description/meshes/typeF_upperbody/LARM_LINK2_mesh.dae</uri>
            </mesh>
          </geometry>
          <material>
            <script>
              <uri>__default__</uri>
              <name>__default__</name>
            </script>
          </material>
        </visual>
        <gravity>1</gravity>
        <velocity_decay/>
        <self_collide>0</self_collide>
        <enable_wind>0</enable_wind>
        <kinematic>0</kinematic>
      </link>
      <joint name='l_shoulder_r_joint' type='revolute'>
        <child>l_shoulder_center</child>
        <parent>l_shoulder_link</parent>
        <axis>
          <xyz>1 0 0</xyz>
          <limit>
            <lower>0</lower>
            <upper>1.5707</upper>
            <effort>10</effort>
            <velocity>0.6</velocity>
          </limit>
          <dynamics>
            <damping>0.2</damping>
            <friction>0</friction>
            <spring_reference>0</spring_reference>
            <spring_stiffness>0</spring_stiffness>
          </dynamics>
          <use_parent_model_frame>1</use_parent_model_frame>
        </axis>
        <physics>
          <ode>
            <implicit_spring_damper>0</implicit_spring_damper>
            <cfm_damping>0</cfm_damping>
            <limit>
              <cfm>0</cfm>
              <erp>0.2</erp>
            </limit>
          </ode>
        </physics>
      </joint>
      <link name='l_upperarm_link'>
        <pose frame=''>-0.01815 0.18398 1.27145 0 -0 0</pose>
        <inertial>
          <pose frame=''>0.005 0 -0.0654 0 -0 0</pose>
          <mass>0.574</mass>
          <inertia>
            <ixx>0.00214</ixx>
            <ixy>0</ixy>
            <ixz>0</ixz>
            <iyy>0.00217</iyy>
            <iyz>0</iyz>
            <izz>0.003</izz>
          </inertia>
        </inertial>
        <collision name='l_upperarm_link_collision'>
          <pose frame=''>-0.005 0 -0.08 0 -0 0</pose>
          <geometry>
            <box>
              <size>0.076 0.065 0.18</size>
            </box>
          </geometry>
          <surface>
            <contact>
              <ode/>
            </contact>
            <friction>
              <ode>
                <mu>0.9</mu>
                <mu2>0.9</mu2>
              </ode>
              <torsional>
                <ode/>
              </torsional>
            </friction>
            <bounce/>
          </surface>
          <max_contacts>10</max_contacts>
        </collision>
        <visual name='l_upperarm_link_visual'>
          <pose frame=''>0 0 0 0 -0 0</pose>
          <geometry>
            <mesh>
              <scale>1 1 1</scale>
              <uri>/home/ubuntu18/ros/melodic/src/seed_r7_ros_pkg/seed_r7_description/meshes/typeF_upperbody/LARM_LINK3_mesh.dae</uri>
            </mesh>
          </geometry>
          <material>
            <script>
              <uri>__default__</uri>
              <name>__default__</name>
            </script>
          </material>
        </visual>
        <gravity>1</gravity>
        <velocity_decay/>
        <self_collide>0</self_collide>
        <enable_wind>0</enable_wind>
        <kinematic>0</kinematic>
      </link>
      <joint name='l_shoulder_y_joint' type='revolute'>
        <child>l_upperarm_link</child>
        <parent>l_shoulder_center</parent>
        <axis>
          <xyz>0 0 1</xyz>
          <limit>
            <lower>-1.5707</lower>
            <upper>0.785398</upper>
            <effort>10</effort>
            <velocity>1.2</velocity>
          </limit>
          <dynamics>
            <damping>0.2</damping>
            <friction>0</friction>
            <spring_reference>0</spring_reference>
            <spring_stiffness>0</spring_stiffness>
          </dynamics>
          <use_parent_model_frame>1</use_parent_model_frame>
        </axis>
        <physics>
          <ode>
            <implicit_spring_damper>0</implicit_spring_damper>
            <cfm_damping>0</cfm_damping>
            <limit>
              <cfm>0</cfm>
              <erp>0.2</erp>
            </limit>
          </ode>
        </physics>
      </joint>
      <link name='l_elbow_link'>
        <pose frame=''>0.01685 0.18398 1.10895 0 -0 0</pose>
        <inertial>
          <pose frame=''>-0.03 0 -0.0546 0 -0 0</pose>
          <mass>0.711</mass>
          <inertia>
            <ixx>0.00178</ixx>
            <ixy>0</ixy>
            <ixz>0</ixz>
            <iyy>0.00179</iyy>
            <iyz>0</iyz>
            <izz>0.0035</izz>
          </inertia>
        </inertial>
        <collision name='l_elbow_link_collision'>
          <pose frame=''>-0.035 0 -0.03 0 -0 0</pose>
          <geometry>
            <box>
              <size>0.06 0.051 0.075</size>
            </box>
          </geometry>
          <surface>
            <contact>
              <ode/>
            </contact>
            <friction>
              <ode>
                <mu>0.9</mu>
                <mu2>0.9</mu2>
              </ode>
              <torsional>
                <ode/>
              </torsional>
            </friction>
            <bounce/>
          </surface>
          <max_contacts>10</max_contacts>
        </collision>
        <visual name='l_elbow_link_visual'>
          <pose frame=''>-0.035 0 -0.035 0 -0 0</pose>
          <geometry>
            <mesh>
              <scale>1 1 1</scale>
              <uri>/home/ubuntu18/ros/melodic/src/seed_r7_ros_pkg/seed_r7_description/meshes/typeF_upperbody/LARM_LINK4_mesh.dae</uri>
            </mesh>
          </geometry>
          <material>
            <script>
              <uri>__default__</uri>
              <name>__default__</name>
            </script>
          </material>
        </visual>
        <gravity>1</gravity>
        <velocity_decay/>
        <self_collide>0</self_collide>
        <enable_wind>0</enable_wind>
        <kinematic>0</kinematic>
      </link>
      <joint name='l_elbow_joint' type='revolute'>
        <child>l_elbow_link</child>
        <parent>l_upperarm_link</parent>
        <axis>
          <xyz>0 1 0</xyz>
          <limit>
            <lower>-3</lower>
            <upper>0</upper>
            <effort>10</effort>
            <velocity>1.2</velocity>
          </limit>
          <dynamics>
            <damping>0.2</damping>
            <friction>0</friction>
            <spring_reference>0</spring_reference>
            <spring_stiffness>0</spring_stiffness>
          </dynamics>
          <use_parent_model_frame>1</use_parent_model_frame>
        </axis>
        <physics>
          <ode>
            <implicit_spring_damper>0</implicit_spring_damper>
            <cfm_damping>0</cfm_damping>
            <limit>
              <cfm>0</cfm>
              <erp>0.2</erp>
            </limit>
          </ode>
        </physics>
      </joint>
      <link name='l_forearm_link'>
        <pose frame=''>-0.01815 0.18398 1.03895 0 -0 0</pose>
        <inertial>
          <pose frame=''>0.006 0 -0.0738 0 -0 0</pose>
          <mass>0.132</mass>
          <inertia>
            <ixx>0.0007</ixx>
            <ixy>0</ixy>
            <ixz>0</ixz>
            <iyy>0.0007</iyy>
            <iyz>0</iyz>
            <izz>0.0004</izz>
          </inertia>
        </inertial>
        <collision name='l_forearm_link_collision'>
          <pose frame=''>0 0 0 0 0 -1.5708</pose>
          <geometry>
            <mesh>
              <scale>1 1 1</scale>
              <uri>/home/ubuntu18/ros/melodic/src/seed_r7_ros_pkg/seed_r7_description/meshes/typeF_upperbody/LARM_LINK5_mesh.dae</uri>
            </mesh>
          </geometry>
          <surface>
            <contact>
              <ode/>
            </contact>
            <friction>
              <ode>
                <mu>0.9</mu>
                <mu2>0.9</mu2>
              </ode>
              <torsional>
                <ode/>
              </torsional>
            </friction>
            <bounce/>
          </surface>
          <max_contacts>10</max_contacts>
        </collision>
        <visual name='l_forearm_link_visual'>
          <pose frame=''>0 0 0 0 0 -1.5708</pose>
          <geometry>
            <mesh>
              <scale>1 1 1</scale>
              <uri>/home/ubuntu18/ros/melodic/src/seed_r7_ros_pkg/seed_r7_description/meshes/typeF_upperbody/LARM_LINK5_mesh.dae</uri>
            </mesh>
          </geometry>
          <material>
            <script>
              <uri>__default__</uri>
              <name>__default__</name>
            </script>
          </material>
        </visual>
        <gravity>1</gravity>
        <velocity_decay/>
        <self_collide>0</self_collide>
        <enable_wind>0</enable_wind>
        <kinematic>0</kinematic>
      </link>
      <joint name='l_wrist_y_joint' type='revolute'>
        <child>l_forearm_link</child>
        <parent>l_elbow_link</parent>
        <axis>
          <xyz>0 0 1</xyz>
          <limit>
            <lower>-1.5707</lower>
            <upper>1.5707</upper>
            <effort>10</effort>
            <velocity>1.3</velocity>
          </limit>
          <dynamics>
            <damping>0.2</damping>
            <friction>0</friction>
            <spring_reference>0</spring_reference>
            <spring_stiffness>0</spring_stiffness>
          </dynamics>
          <use_parent_model_frame>1</use_parent_model_frame>
        </axis>
        <physics>
          <ode>
            <implicit_spring_damper>0</implicit_spring_damper>
            <cfm_damping>0</cfm_damping>
            <limit>
              <cfm>0</cfm>
              <erp>0.2</erp>
            </limit>
          </ode>
        </physics>
      </joint>
      <link name='l_wrist_center'>
        <pose frame=''>-0.01815 0.18398 0.843446 0 -0 0</pose>
        <inertial>
          <pose frame=''>0 0 0 0 -0 0</pose>
          <mass>0.05</mass>
          <inertia>
            <ixx>0.0001</ixx>
            <ixy>0</ixy>
            <ixz>0</ixz>
            <iyy>0.0001</iyy>
            <iyz>0</iyz>
            <izz>0.0001</izz>
          </inertia>
        </inertial>
        <gravity>1</gravity>
        <velocity_decay/>
        <self_collide>0</self_collide>
        <enable_wind>0</enable_wind>
        <kinematic>0</kinematic>
      </link>
      <joint name='l_wrist_p_joint' type='revolute'>
        <child>l_wrist_center</child>
        <parent>l_forearm_link</parent>
        <axis>
          <xyz>0 1 0</xyz>
          <limit>
            <lower>-0.087</lower>
            <upper>0.087</upper>
            <effort>10</effort>
            <velocity>0.9</velocity>
          </limit>
          <dynamics>
            <damping>0.2</damping>
            <friction>0</friction>
            <spring_reference>0</spring_reference>
            <spring_stiffness>0</spring_stiffness>
          </dynamics>
          <use_parent_model_frame>1</use_parent_model_frame>
        </axis>
        <physics>
          <ode>
            <implicit_spring_damper>0</implicit_spring_damper>
            <cfm_damping>0</cfm_damping>
            <limit>
              <cfm>0</cfm>
              <erp>0.2</erp>
            </limit>
          </ode>
        </physics>
      </joint>
      <link name='l_hand_link'>
        <pose frame=''>-0.01815 0.18398 0.843446 0 -0 0</pose>
        <inertial>
          <pose frame=''>0 0 -0.0875 0 -0 0</pose>
          <mass>0.183</mass>
          <inertia>
            <ixx>0.000601</ixx>
            <ixy>0</ixy>
            <ixz>0</ixz>
            <iyy>0.00055</iyy>
            <iyz>0</iyz>
            <izz>0.000102</izz>
          </inertia>
        </inertial>
        <collision name='l_hand_link_collision'>
          <pose frame=''>0 0 -0.093 -0.7 0 0</pose>
          <geometry>
            <box>
              <size>0.036 0.07 0.03</size>
            </box>
          </geometry>
          <surface>
            <contact>
              <ode/>
            </contact>
            <friction>
              <ode>
                <mu>0.9</mu>
                <mu2>0.9</mu2>
              </ode>
              <torsional>
                <ode/>
              </torsional>
            </friction>
            <bounce/>
          </surface>
          <max_contacts>10</max_contacts>
        </collision>
        <collision name='l_hand_link_collision_1'>
          <pose frame=''>0 0.007 -0.055 0.1 -0 0</pose>
          <geometry>
            <box>
              <size>0.036 0.05 0.07</size>
            </box>
          </geometry>
          <surface>
            <contact>
              <ode/>
            </contact>
            <friction>
              <ode>
                <mu>0.9</mu>
                <mu2>0.9</mu2>
              </ode>
              <torsional>
                <ode/>
              </torsional>
            </friction>
            <bounce/>
          </surface>
          <max_contacts>10</max_contacts>
        </collision>
        <visual name='l_hand_link_visual'>
          <pose frame=''>0 0 0 0 -0 -3.14159</pose>
          <geometry>
            <mesh>
              <scale>1 1 1</scale>
              <uri>/home/ubuntu18/ros/melodic/src/seed_r7_ros_pkg/seed_r7_description/meshes/trx_s/RARM_LINK7_mesh.dae</uri>
            </mesh>
          </geometry>
          <material>
            <script>
              <uri>__default__</uri>
              <name>__default__</name>
            </script>
          </material>
        </visual>
        <gravity>1</gravity>
        <velocity_decay/>
        <self_collide>0</self_collide>
        <enable_wind>0</enable_wind>
        <kinematic>0</kinematic>
      </link>
      <joint name='l_wrist_r_joint' type='revolute'>
        <child>l_hand_link</child>
        <parent>l_wrist_center</parent>
        <axis>
          <xyz>1 0 0</xyz>
          <limit>
            <lower>-1.484</lower>
            <upper>0.436</upper>
            <effort>10</effort>
            <velocity>2.1</velocity>
          </limit>
          <dynamics>
            <damping>0.2</damping>
            <friction>0</friction>
            <spring_reference>0</spring_reference>
            <spring_stiffness>0</spring_stiffness>
          </dynamics>
          <use_parent_model_frame>1</use_parent_model_frame>
        </axis>
        <physics>
          <ode>
            <implicit_spring_damper>0</implicit_spring_damper>
            <cfm_damping>0</cfm_damping>
            <limit>
              <cfm>0</cfm>
              <erp>0.2</erp>
            </limit>
          </ode>
        </physics>
      </joint>
      <link name='l_indexbase_link'>
        <pose frame=''>-0.01815 0.19698 0.728446 0 -0 0</pose>
        <inertial>
          <pose frame=''>0 -0.042408 -0.037196 0 -0 0</pose>
          <mass>0.3</mass>
          <inertia>
            <ixx>0.00230024</ixx>
            <ixy>0</ixy>
            <ixz>0</ixz>
            <iyy>0.00034078</iyy>
            <iyz>-7.64367e-05</iyz>
            <izz>0.000459461</izz>
          </inertia>
        </inertial>
        <collision name='l_indexbase_link_collision'>
          <pose frame=''>0.015 -0.013494 -0.021422 0.85 -0 0</pose>
          <geometry>
            <box>
              <size>0.01 0.061 0.016</size>
            </box>
          </geometry>
          <surface>
            <contact>
              <ode/>
            </contact>
            <friction>
              <ode>
                <mu>0.9</mu>
                <mu2>0.9</mu2>
              </ode>
              <torsional>
                <ode/>
              </torsional>
            </friction>
            <bounce/>
          </surface>
          <max_contacts>10</max_contacts>
        </collision>
        <collision name='l_indexbase_link_collision_1'>
          <pose frame=''>-0.015 -0.013494 -0.021422 0.85 -0 0</pose>
          <geometry>
            <box>
              <size>0.01 0.061 0.016</size>
            </box>
          </geometry>
          <surface>
            <contact>
              <ode/>
            </contact>
            <friction>
              <ode>
                <mu>0.9</mu>
                <mu2>0.9</mu2>
              </ode>
              <torsional>
                <ode/>
              </torsional>
            </friction>
            <bounce/>
          </surface>
          <max_contacts>10</max_contacts>
        </collision>
        <collision name='l_indexbase_link_fixed_joint_lump__l_indexmid_link_collision_2'>
          <pose frame=''>0.015 -0.042754 -0.042615 0.3 -0 0</pose>
          <geometry>
            <box>
              <size>0.01 0.03 0.016</size>
            </box>
          </geometry>
          <surface>
            <contact>
              <ode/>
            </contact>
            <friction>
              <ode>
                <mu>0.9</mu>
                <mu2>0.9</mu2>
              </ode>
              <torsional>
                <ode/>
              </torsional>
            </friction>
            <bounce/>
          </surface>
          <max_contacts>10</max_contacts>
        </collision>
        <collision name='l_indexbase_link_fixed_joint_lump__l_indexmid_link_collision_3'>
          <pose frame=''>-0.015 -0.042754 -0.042615 0.3 -0 0</pose>
          <geometry>
            <box>
              <size>0.01 0.03 0.016</size>
            </box>
          </geometry>
          <surface>
            <contact>
              <ode/>
            </contact>
            <friction>
              <ode>
                <mu>0.9</mu>
                <mu2>0.9</mu2>
              </ode>
              <torsional>
                <ode/>
              </torsional>
            </friction>
            <bounce/>
          </surface>
          <max_contacts>10</max_contacts>
        </collision>
        <collision name='l_indexbase_link_fixed_joint_lump__l_indexend_link_collision_4'>
          <pose frame=''>0.015 -0.06347 -0.043972 0 -0 0</pose>
          <geometry>
            <box>
              <size>0.01 0.028 0.016</size>
            </box>
          </geometry>
          <surface>
            <contact>
              <ode/>
            </contact>
            <friction>
              <ode>
                <mu>0.9</mu>
                <mu2>0.9</mu2>
              </ode>
              <torsional>
                <ode/>
              </torsional>
            </friction>
            <bounce/>
          </surface>
          <max_contacts>10</max_contacts>
        </collision>
        <collision name='l_indexbase_link_fixed_joint_lump__l_indexend_link_collision_5'>
          <pose frame=''>-0.015 -0.06347 -0.043972 0 -0 0</pose>
          <geometry>
            <box>
              <size>0.01 0.028 0.016</size>
            </box>
          </geometry>
          <surface>
            <contact>
              <ode/>
            </contact>
            <friction>
              <ode>
                <mu>0.9</mu>
                <mu2>0.9</mu2>
              </ode>
              <torsional>
                <ode/>
              </torsional>
            </friction>
            <bounce/>
          </surface>
          <max_contacts>10</max_contacts>
        </collision>
        <visual name='l_indexbase_link_visual'>
          <pose frame=''>0 -0.013 0.115 0 -0 -3.14159</pose>
          <geometry>
            <mesh>
              <scale>1 1 1</scale>
              <uri>/home/ubuntu18/ros/melodic/src/seed_r7_ros_pkg/seed_r7_description/meshes/trx_s/RARM_INDEX_LINK1_mesh.dae</uri>
            </mesh>
          </geometry>
          <material>
            <script>
              <uri>__default__</uri>
              <name>__default__</name>
            </script>
          </material>
        </visual>
        <visual name='l_indexbase_link_fixed_joint_lump__l_indexmid_link_visual_1'>
          <pose frame=''>0 -0.013 0.115 0 -0 -3.14159</pose>
          <geometry>
            <mesh>
              <scale>1 1 1</scale>
              <uri>/home/ubuntu18/ros/melodic/src/seed_r7_ros_pkg/seed_r7_description/meshes/trx_s/RARM_INDEX_LINK2_mesh.dae</uri>
            </mesh>
          </geometry>
          <material>
            <script>
              <uri>__default__</uri>
              <name>__default__</name>
            </script>
          </material>
        </visual>
        <visual name='l_indexbase_link_fixed_joint_lump__l_indexend_link_visual_2'>
          <pose frame=''>0 -0.013 0.115 0 -0 -3.14159</pose>
          <geometry>
            <mesh>
              <scale>1 1 1</scale>
              <uri>/home/ubuntu18/ros/melodic/src/seed_r7_ros_pkg/seed_r7_description/meshes/trx_s/RARM_INDEX_LINK3_mesh.dae</uri>
            </mesh>
          </geometry>
          <material>
            <script>
              <uri>__default__</uri>
              <name>__default__</name>
            </script>
          </material>
        </visual>
        <velocity_decay/>
        <velocity_decay/>
        <gravity>1</gravity>
        <velocity_decay/>
        <self_collide>0</self_collide>
        <enable_wind>0</enable_wind>
        <kinematic>0</kinematic>
      </link>
      <joint name='l_indexbase_joint' type='revolute'>
        <child>l_indexbase_link</child>
        <parent>l_hand_link</parent>
        <axis>
          <xyz>1 0 0</xyz>
          <limit>
            <lower>-1e+16</lower>
            <upper>1e+16</upper>
          </limit>
          <dynamics>
            <spring_reference>0</spring_reference>
            <spring_stiffness>0</spring_stiffness>
          </dynamics>
          <use_parent_model_frame>1</use_parent_model_frame>
        </axis>
      </joint>
      <link name='l_thumb_link'>
        <pose frame=''>-0.01815 0.161625 0.763801 0 -0 0</pose>
        <inertial>
          <pose frame=''>0 -0.05 -0.06 0 -0 0</pose>
          <mass>0.1</mass>
          <inertia>
            <ixx>0.001</ixx>
            <ixy>0</ixy>
            <ixz>0</ixz>
            <iyy>0.0001</iyy>
            <iyz>0</iyz>
            <izz>0.0001</izz>
          </inertia>
        </inertial>
        <collision name='l_thumb_link_collision'>
          <pose frame=''>0 -0.019645 -0.010355 -0.63 0 0</pose>
          <geometry>
            <box>
              <size>0.012 0.008 0.05</size>
            </box>
          </geometry>
          <surface>
            <contact>
              <ode/>
            </contact>
            <friction>
              <ode>
                <mu>0.9</mu>
                <mu2>0.9</mu2>
              </ode>
              <torsional>
                <ode/>
              </torsional>
            </friction>
            <bounce/>
          </surface>
          <max_contacts>10</max_contacts>
        </collision>
        <collision name='l_thumb_link_collision_1'>
          <pose frame=''>0 -0.035645 -0.050355 -0.1 0 0</pose>
          <geometry>
            <box>
              <size>0.012 0.008 0.05</size>
            </box>
          </geometry>
          <surface>
            <contact>
              <ode/>
            </contact>
            <friction>
              <ode>
                <mu>0.9</mu>
                <mu2>0.9</mu2>
              </ode>
              <torsional>
                <ode/>
              </torsional>
            </friction>
            <bounce/>
          </surface>
          <max_contacts>10</max_contacts>
        </collision>
        <visual name='l_thumb_link_visual'>
          <pose frame=''>0 0.022355 0.079645 0 -0 -3.14159</pose>
          <geometry>
            <mesh>
              <scale>1 1 1</scale>
              <uri>/home/ubuntu18/ros/melodic/src/seed_r7_ros_pkg/seed_r7_description/meshes/trx_s/RARM_THUMB_LINK_mesh.dae</uri>
            </mesh>
          </geometry>
          <material>
            <script>
              <uri>__default__</uri>
              <name>__default__</name>
            </script>
          </material>
        </visual>
        <gravity>1</gravity>
        <velocity_decay/>
        <self_collide>0</self_collide>
        <enable_wind>0</enable_wind>
        <kinematic>0</kinematic>
      </link>
      <joint name='l_thumb_joint' type='revolute'>
        <child>l_thumb_link</child>
        <parent>l_hand_link</parent>
        <axis>
          <xyz>1 0 0</xyz>
          <limit>
            <lower>-1</lower>
            <upper>1</upper>
            <effort>50</effort>
            <velocity>0.5</velocity>
          </limit>
          <dynamics>
            <damping>0.2</damping>
            <friction>0</friction>
            <spring_reference>0</spring_reference>
            <spring_stiffness>0</spring_stiffness>
          </dynamics>
          <use_parent_model_frame>1</use_parent_model_frame>
        </axis>
        <physics>
          <ode>
            <implicit_spring_damper>0</implicit_spring_damper>
            <cfm_damping>0</cfm_damping>
            <limit>
              <cfm>0</cfm>
              <erp>0.2</erp>
            </limit>
          </ode>
        </physics>
      </joint>
      <link name='neck_link'>
        <pose frame=''>0 0 1.419 0 -0 0</pose>
        <inertial>
          <pose frame=''>0 0 0.0595 0 -0 0</pose>
          <mass>0.341</mass>
          <inertia>
            <ixx>0.001</ixx>
            <ixy>0</ixy>
            <ixz>0</ixz>
            <iyy>0.001</iyy>
            <iyz>0</iyz>
            <izz>0.002</izz>
          </inertia>
        </inertial>
        <collision name='neck_link_collision'>
          <pose frame=''>0 0 0 0 -0 0</pose>
          <geometry>
            <mesh>
              <scale>1 1 1</scale>
              <uri>/home/ubuntu18/ros/melodic/src/seed_r7_ros_pkg/seed_r7_description/meshes/typeF_upperbody/NECK_LINK1_mesh.dae</uri>
            </mesh>
          </geometry>
          <surface>
            <contact>
              <ode/>
            </contact>
            <friction>
              <ode>
                <mu>0.9</mu>
                <mu2>0.9</mu2>
              </ode>
              <torsional>
                <ode/>
              </torsional>
            </friction>
            <bounce/>
          </surface>
          <max_contacts>10</max_contacts>
        </collision>
        <visual name='neck_link_visual'>
          <pose frame=''>0 0 0 0 -0 0</pose>
          <geometry>
            <mesh>
              <scale>1 1 1</scale>
              <uri>/home/ubuntu18/ros/melodic/src/seed_r7_ros_pkg/seed_r7_description/meshes/typeF_upperbody/NECK_LINK1_mesh.dae</uri>
            </mesh>
          </geometry>
          <material>
            <script>
              <uri>__default__</uri>
              <name>__default__</name>
            </script>
          </material>
        </visual>
        <gravity>1</gravity>
        <velocity_decay/>
        <self_collide>0</self_collide>
        <enable_wind>0</enable_wind>
        <kinematic>0</kinematic>
      </link>
      <joint name='neck_y_joint' type='revolute'>
        <child>neck_link</child>
        <parent>body_link</parent>
        <axis>
          <xyz>0 0 1</xyz>
          <limit>
            <lower>-2.09</lower>
            <upper>2.09</upper>
            <effort>10</effort>
            <velocity>1.6</velocity>
          </limit>
          <dynamics>
            <damping>0.2</damping>
            <friction>0</friction>
            <spring_reference>0</spring_reference>
            <spring_stiffness>0</spring_stiffness>
          </dynamics>
          <use_parent_model_frame>1</use_parent_model_frame>
        </axis>
        <physics>
          <ode>
            <implicit_spring_damper>0</implicit_spring_damper>
            <cfm_damping>0</cfm_damping>
            <limit>
              <cfm>0</cfm>
              <erp>0.2</erp>
            </limit>
          </ode>
        </physics>
      </joint>
      <link name='head_base_link'>
        <pose frame=''>0 0 1.5235 0 -0 0</pose>
        <inertial>
          <pose frame=''>0 0 0 0 -0 0</pose>
          <mass>0.1</mass>
          <inertia>
            <ixx>0.0005</ixx>
            <ixy>0</ixy>
            <ixz>0</ixz>
            <iyy>0.0005</iyy>
            <iyz>0</iyz>
            <izz>0.0005</izz>
          </inertia>
        </inertial>
        <collision name='head_base_link_collision'>
          <pose frame=''>0 0 0 0 -0 0</pose>
          <geometry>
            <mesh>
              <scale>1 1 1</scale>
              <uri>/home/ubuntu18/ros/melodic/src/seed_r7_ros_pkg/seed_r7_description/meshes/typeF_upperbody/NECK_LINK2_mesh.dae</uri>
            </mesh>
          </geometry>
          <surface>
            <contact>
              <ode/>
            </contact>
            <friction>
              <ode>
                <mu>0.9</mu>
                <mu2>0.9</mu2>
              </ode>
              <torsional>
                <ode/>
              </torsional>
            </friction>
            <bounce/>
          </surface>
          <max_contacts>10</max_contacts>
        </collision>
        <visual name='head_base_link_visual'>
          <pose frame=''>0 0 0 0 -0 0</pose>
          <geometry>
            <mesh>
              <scale>1 1 1</scale>
              <uri>/home/ubuntu18/ros/melodic/src/seed_r7_ros_pkg/seed_r7_description/meshes/typeF_upperbody/NECK_LINK2_mesh.dae</uri>
            </mesh>
          </geometry>
          <material>
            <script>
              <uri>__default__</uri>
              <name>__default__</name>
            </script>
          </material>
        </visual>
        <gravity>1</gravity>
        <velocity_decay/>
        <self_collide>0</self_collide>
        <enable_wind>0</enable_wind>
        <kinematic>0</kinematic>
      </link>
      <joint name='neck_p_joint' type='revolute'>
        <child>head_base_link</child>
        <parent>neck_link</parent>
        <axis>
          <xyz>0 1 0</xyz>
          <limit>
            <lower>-0.262</lower>
            <upper>0.96</upper>
            <effort>10</effort>
            <velocity>2.1</velocity>
          </limit>
          <dynamics>
            <damping>0.2</damping>
            <friction>0</friction>
            <spring_reference>0</spring_reference>
            <spring_stiffness>0</spring_stiffness>
          </dynamics>
          <use_parent_model_frame>1</use_parent_model_frame>
        </axis>
        <physics>
          <ode>
            <implicit_spring_damper>0</implicit_spring_damper>
            <cfm_damping>0</cfm_damping>
            <limit>
              <cfm>0</cfm>
              <erp>0.2</erp>
            </limit>
          </ode>
        </physics>
      </joint>
      <link name='head_link'>
        <pose frame=''>0 0 1.5235 0 -0 0</pose>
        <inertial>
          <pose frame=''>0.01 0 0.07 0 -0 0</pose>
          <mass>0.974</mass>
          <inertia>
            <ixx>0.005</ixx>
            <ixy>0</ixy>
            <ixz>0</ixz>
            <iyy>0.005</iyy>
            <iyz>0</iyz>
            <izz>0.005</izz>
          </inertia>
        </inertial>
        <collision name='head_link_collision'>
          <pose frame=''>0 0 0 0 -0 0</pose>
          <geometry>
            <mesh>
              <scale>1 1 1</scale>
              <uri>/home/ubuntu18/ros/melodic/src/seed_r7_ros_pkg/seed_r7_description/meshes/typeF_upperbody/NECK_LINK3_mesh.dae</uri>
            </mesh>
          </geometry>
          <surface>
            <contact>
              <ode/>
            </contact>
            <friction>
              <ode>
                <mu>0.9</mu>
                <mu2>0.9</mu2>
              </ode>
              <torsional>
                <ode/>
              </torsional>
            </friction>
            <bounce/>
          </surface>
          <max_contacts>10</max_contacts>
        </collision>
        <visual name='head_link_visual'>
          <pose frame=''>0 0 0 0 -0 0</pose>
          <geometry>
            <mesh>
              <scale>1 1 1</scale>
              <uri>/home/ubuntu18/ros/melodic/src/seed_r7_ros_pkg/seed_r7_description/meshes/typeF_upperbody/NECK_LINK3_mesh.dae</uri>
            </mesh>
          </geometry>
          <material>
            <script>
              <uri>__default__</uri>
              <name>__default__</name>
            </script>
          </material>
        </visual>
        <velocity_decay/>
        <gravity>1</gravity>
        <velocity_decay/>
        <sensor name='camera1' type='depth'>
          <update_rate>0</update_rate>
          <camera name='camera_ir'>
            <horizontal_fov>1.7</horizontal_fov>
            <image>
              <width>640</width>
              <height>480</height>
              <format>B8G8R8</format>
            </image>
            <clip>
              <near>0.15</near>
              <far>300</far>
            </clip>
          </camera>
          <plugin name='camera_controller' filename='libgazebo_ros_depth_camera.so'>
            <alwaysOn>1</alwaysOn>
            <updateRate>0.0</updateRate>
            <cameraName>camera</cameraName>
            <imageTopicName>image_raw</imageTopicName>
            <cameraInfoTopicName>camera_info</cameraInfoTopicName>
            <depthImageTopicName>depth/image_raw</depthImageTopicName>
            <depthImageCameraInfoTopicName>depth/camera_info</depthImageCameraInfoTopicName>
            <pointCloudTopicName>points</pointCloudTopicName>
            <frameName>camera_optical_frame</frameName>
            <hackBaseline>0.07</hackBaseline>
            <pointCloudCutoff>0.5</pointCloudCutoff>
            <pointCloudCutoffMax>3.0</pointCloudCutoffMax>
            <distortionK1>0.0</distortionK1>
            <distortionK2>0.0</distortionK2>
            <distortionK3>0.0</distortionK3>
            <distortionT1>0.0</distortionT1>
            <distortionT2>0.0</distortionT2>
            <robotNamespace>/</robotNamespace>
          </plugin>
          <pose frame=''>0 0.035 0.09 0 0.15 0</pose>
        </sensor>
        <self_collide>0</self_collide>
        <enable_wind>0</enable_wind>
        <kinematic>0</kinematic>
      </link>
      <joint name='neck_r_joint' type='revolute'>
        <child>head_link</child>
        <parent>head_base_link</parent>
        <axis>
          <xyz>1 0 0</xyz>
          <limit>
            <lower>-0.087</lower>
            <upper>0.087</upper>
            <effort>10</effort>
            <velocity>0.9</velocity>
          </limit>
          <dynamics>
            <damping>0.2</damping>
            <friction>0</friction>
            <spring_reference>0</spring_reference>
            <spring_stiffness>0</spring_stiffness>
          </dynamics>
          <use_parent_model_frame>1</use_parent_model_frame>
        </axis>
        <physics>
          <ode>
            <implicit_spring_damper>0</implicit_spring_damper>
            <cfm_damping>0</cfm_damping>
            <limit>
              <cfm>0</cfm>
              <erp>0.2</erp>
            </limit>
          </ode>
        </physics>
      </joint>
      <link name='r_shoulder_link'>
        <pose frame=''>-0.01815 -0.1342 1.3704 0 -0 0</pose>
        <inertial>
          <pose frame=''>0 -0.02 0.015 0 -0 0</pose>
          <mass>0.242</mass>
          <inertia>
            <ixx>0.00133</ixx>
            <ixy>0</ixy>
            <ixz>0</ixz>
            <iyy>0.001</iyy>
            <iyz>0</iyz>
            <izz>0.00133</izz>
          </inertia>
        </inertial>
        <collision name='r_shoulder_link_collision'>
          <pose frame=''>0 0 0 0.174533 -0 0</pose>
          <geometry>
            <mesh>
              <scale>1 1 1</scale>
              <uri>/home/ubuntu18/ros/melodic/src/seed_r7_ros_pkg/seed_r7_description/meshes/typeF_upperbody/RARM_LINK1_mesh.dae</uri>
            </mesh>
          </geometry>
          <surface>
            <contact>
              <ode/>
            </contact>
            <friction>
              <ode>
                <mu>0.9</mu>
                <mu2>0.9</mu2>
              </ode>
              <torsional>
                <ode/>
              </torsional>
            </friction>
            <bounce/>
          </surface>
          <max_contacts>10</max_contacts>
        </collision>
        <visual name='r_shoulder_link_visual'>
          <pose frame=''>0 0 0 0.174533 -0 0</pose>
          <geometry>
            <mesh>
              <scale>1 1 1</scale>
              <uri>/home/ubuntu18/ros/melodic/src/seed_r7_ros_pkg/seed_r7_description/meshes/typeF_upperbody/RARM_LINK1_mesh.dae</uri>
            </mesh>
          </geometry>
          <material>
            <script>
              <uri>__default__</uri>
              <name>__default__</name>
            </script>
          </material>
        </visual>
        <gravity>1</gravity>
        <velocity_decay/>
        <self_collide>0</self_collide>
        <enable_wind>0</enable_wind>
        <kinematic>0</kinematic>
      </link>
      <joint name='r_shoulder_p_joint' type='revolute'>
        <child>r_shoulder_link</child>
        <parent>body_link</parent>
        <axis>
          <xyz>0 0.984808 0.173648</xyz>
          <limit>
            <lower>-1.535</lower>
            <upper>0.261</upper>
            <effort>10</effort>
            <velocity>0.4</velocity>
          </limit>
          <dynamics>
            <damping>0.2</damping>
            <friction>0</friction>
            <spring_reference>0</spring_reference>
            <spring_stiffness>0</spring_stiffness>
          </dynamics>
          <use_parent_model_frame>1</use_parent_model_frame>
        </axis>
        <physics>
          <ode>
            <implicit_spring_damper>0</implicit_spring_damper>
            <cfm_damping>0</cfm_damping>
            <limit>
              <cfm>0</cfm>
              <erp>0.2</erp>
            </limit>
          </ode>
        </physics>
      </joint>
      <link name='r_shoulder_center'>
        <pose frame=''>-0.01815 -0.193978 1.39845 0 -0 0</pose>
        <inertial>
          <pose frame=''>0 0.01 -0.06 0 -0 0</pose>
          <mass>0.744</mass>
          <inertia>
            <ixx>0.000841</ixx>
            <ixy>0</ixy>
            <ixz>0</ixz>
            <iyy>0.000835</iyy>
            <iyz>0</iyz>
            <izz>0.000305</izz>
          </inertia>
        </inertial>
        <collision name='r_shoulder_center_collision'>
          <pose frame=''>0 0 0 0 -0 0</pose>
          <geometry>
            <mesh>
              <scale>1 1 1</scale>
              <uri>/home/ubuntu18/ros/melodic/src/seed_r7_ros_pkg/seed_r7_description/meshes/typeF_upperbody/RARM_LINK2_mesh.dae</uri>
            </mesh>
          </geometry>
          <surface>
            <contact>
              <ode/>
            </contact>
            <friction>
              <ode>
                <mu>0.9</mu>
                <mu2>0.9</mu2>
              </ode>
              <torsional>
                <ode/>
              </torsional>
            </friction>
            <bounce/>
          </surface>
          <max_contacts>10</max_contacts>
        </collision>
        <visual name='r_shoulder_center_visual'>
          <pose frame=''>0 0 0 0 -0 0</pose>
          <geometry>
            <mesh>
              <scale>1 1 1</scale>
              <uri>/home/ubuntu18/ros/melodic/src/seed_r7_ros_pkg/seed_r7_description/meshes/typeF_upperbody/RARM_LINK2_mesh.dae</uri>
            </mesh>
          </geometry>
          <material>
            <script>
              <uri>__default__</uri>
              <name>__default__</name>
            </script>
          </material>
        </visual>
        <gravity>1</gravity>
        <velocity_decay/>
        <self_collide>0</self_collide>
        <enable_wind>0</enable_wind>
        <kinematic>0</kinematic>
      </link>
      <joint name='r_shoulder_r_joint' type='revolute'>
        <child>r_shoulder_center</child>
        <parent>r_shoulder_link</parent>
        <axis>
          <xyz>1 0 0</xyz>
          <limit>
            <lower>-1.5707</lower>
            <upper>0</upper>
            <effort>10</effort>
            <velocity>0.6</velocity>
          </limit>
          <dynamics>
            <damping>0.2</damping>
            <friction>0</friction>
            <spring_reference>0</spring_reference>
            <spring_stiffness>0</spring_stiffness>
          </dynamics>
          <use_parent_model_frame>1</use_parent_model_frame>
        </axis>
        <physics>
          <ode>
            <implicit_spring_damper>0</implicit_spring_damper>
            <cfm_damping>0</cfm_damping>
            <limit>
              <cfm>0</cfm>
              <erp>0.2</erp>
            </limit>
          </ode>
        </physics>
      </joint>
      <link name='r_upperarm_link'>
        <pose frame=''>-0.01815 -0.183978 1.27145 0 -0 0</pose>
        <inertial>
          <pose frame=''>0.005 0 -0.0654 0 -0 0</pose>
          <mass>0.574</mass>
          <inertia>
            <ixx>0.00214</ixx>
            <ixy>0</ixy>
            <ixz>0</ixz>
            <iyy>0.00217</iyy>
            <iyz>0</iyz>
            <izz>0.003</izz>
          </inertia>
        </inertial>
        <collision name='r_upperarm_link_collision'>
          <pose frame=''>-0.005 0 -0.08 0 -0 0</pose>
          <geometry>
            <box>
              <size>0.076 0.065 0.18</size>
            </box>
          </geometry>
          <surface>
            <contact>
              <ode/>
            </contact>
            <friction>
              <ode>
                <mu>0.9</mu>
                <mu2>0.9</mu2>
              </ode>
              <torsional>
                <ode/>
              </torsional>
            </friction>
            <bounce/>
          </surface>
          <max_contacts>10</max_contacts>
        </collision>
        <visual name='r_upperarm_link_visual'>
          <pose frame=''>0 0 0 0 -0 0</pose>
          <geometry>
            <mesh>
              <scale>1 1 1</scale>
              <uri>/home/ubuntu18/ros/melodic/src/seed_r7_ros_pkg/seed_r7_description/meshes/typeF_upperbody/RARM_LINK3_mesh.dae</uri>
            </mesh>
          </geometry>
          <material>
            <script>
              <uri>__default__</uri>
              <name>__default__</name>
            </script>
          </material>
        </visual>
        <gravity>1</gravity>
        <velocity_decay/>
        <self_collide>0</self_collide>
        <enable_wind>0</enable_wind>
        <kinematic>0</kinematic>
      </link>
      <joint name='r_shoulder_y_joint' type='revolute'>
        <child>r_upperarm_link</child>
        <parent>r_shoulder_center</parent>
        <axis>
          <xyz>0 0 1</xyz>
          <limit>
            <lower>-0.785398</lower>
            <upper>1.5707</upper>
            <effort>10</effort>
            <velocity>1.2</velocity>
          </limit>
          <dynamics>
            <damping>0.2</damping>
            <friction>0</friction>
            <spring_reference>0</spring_reference>
            <spring_stiffness>0</spring_stiffness>
          </dynamics>
          <use_parent_model_frame>1</use_parent_model_frame>
        </axis>
        <physics>
          <ode>
            <implicit_spring_damper>0</implicit_spring_damper>
            <cfm_damping>0</cfm_damping>
            <limit>
              <cfm>0</cfm>
              <erp>0.2</erp>
            </limit>
          </ode>
        </physics>
      </joint>
      <link name='r_elbow_link'>
        <pose frame=''>0.01685 -0.183978 1.10895 0 -0 0</pose>
        <inertial>
          <pose frame=''>-0.03 0 -0.0546 0 -0 0</pose>
          <mass>0.711</mass>
          <inertia>
            <ixx>0.00178</ixx>
            <ixy>0</ixy>
            <ixz>0</ixz>
            <iyy>0.00179</iyy>
            <iyz>0</iyz>
            <izz>0.0035</izz>
          </inertia>
        </inertial>
        <collision name='r_elbow_link_collision'>
          <pose frame=''>-0.035 0 -0.03 0 -0 0</pose>
          <geometry>
            <box>
              <size>0.06 0.051 0.075</size>
            </box>
          </geometry>
          <surface>
            <contact>
              <ode/>
            </contact>
            <friction>
              <ode>
                <mu>0.9</mu>
                <mu2>0.9</mu2>
              </ode>
              <torsional>
                <ode/>
              </torsional>
            </friction>
            <bounce/>
          </surface>
          <max_contacts>10</max_contacts>
        </collision>
        <visual name='r_elbow_link_visual'>
          <pose frame=''>-0.035 0 -0.035 0 -0 0</pose>
          <geometry>
            <mesh>
              <scale>1 1 1</scale>
              <uri>/home/ubuntu18/ros/melodic/src/seed_r7_ros_pkg/seed_r7_description/meshes/typeF_upperbody/RARM_LINK4_mesh.dae</uri>
            </mesh>
          </geometry>
          <material>
            <script>
              <uri>__default__</uri>
              <name>__default__</name>
            </script>
          </material>
        </visual>
        <gravity>1</gravity>
        <velocity_decay/>
        <self_collide>0</self_collide>
        <enable_wind>0</enable_wind>
        <kinematic>0</kinematic>
      </link>
      <joint name='r_elbow_joint' type='revolute'>
        <child>r_elbow_link</child>
        <parent>r_upperarm_link</parent>
        <axis>
          <xyz>0 1 0</xyz>
          <limit>
            <lower>-3</lower>
            <upper>0</upper>
            <effort>10</effort>
            <velocity>1.2</velocity>
          </limit>
          <dynamics>
            <damping>0.2</damping>
            <friction>0</friction>
            <spring_reference>0</spring_reference>
            <spring_stiffness>0</spring_stiffness>
          </dynamics>
          <use_parent_model_frame>1</use_parent_model_frame>
        </axis>
        <physics>
          <ode>
            <implicit_spring_damper>0</implicit_spring_damper>
            <cfm_damping>0</cfm_damping>
            <limit>
              <cfm>0</cfm>
              <erp>0.2</erp>
            </limit>
          </ode>
        </physics>
      </joint>
      <link name='r_forearm_link'>
        <pose frame=''>-0.01815 -0.183978 1.03895 0 -0 0</pose>
        <inertial>
          <pose frame=''>0.006 0 -0.0738 0 -0 0</pose>
          <mass>0.132</mass>
          <inertia>
            <ixx>0.0007</ixx>
            <ixy>0</ixy>
            <ixz>0</ixz>
            <iyy>0.0007</iyy>
            <iyz>0</iyz>
            <izz>0.0004</izz>
          </inertia>
        </inertial>
        <collision name='r_forearm_link_collision'>
          <pose frame=''>0 0 0 0 -0 1.5708</pose>
          <geometry>
            <mesh>
              <scale>1 1 1</scale>
              <uri>/home/ubuntu18/ros/melodic/src/seed_r7_ros_pkg/seed_r7_description/meshes/typeF_upperbody/RARM_LINK5_mesh.dae</uri>
            </mesh>
          </geometry>
          <surface>
            <contact>
              <ode/>
            </contact>
            <friction>
              <ode>
                <mu>0.9</mu>
                <mu2>0.9</mu2>
              </ode>
              <torsional>
                <ode/>
              </torsional>
            </friction>
            <bounce/>
          </surface>
          <max_contacts>10</max_contacts>
        </collision>
        <visual name='r_forearm_link_visual'>
          <pose frame=''>0 0 0 0 -0 1.5708</pose>
          <geometry>
            <mesh>
              <scale>1 1 1</scale>
              <uri>/home/ubuntu18/ros/melodic/src/seed_r7_ros_pkg/seed_r7_description/meshes/typeF_upperbody/RARM_LINK5_mesh.dae</uri>
            </mesh>
          </geometry>
          <material>
            <script>
              <uri>__default__</uri>
              <name>__default__</name>
            </script>
          </material>
        </visual>
        <gravity>1</gravity>
        <velocity_decay/>
        <self_collide>0</self_collide>
        <enable_wind>0</enable_wind>
        <kinematic>0</kinematic>
      </link>
      <joint name='r_wrist_y_joint' type='revolute'>
        <child>r_forearm_link</child>
        <parent>r_elbow_link</parent>
        <axis>
          <xyz>0 0 1</xyz>
          <limit>
            <lower>-1.5707</lower>
            <upper>1.5707</upper>
            <effort>10</effort>
            <velocity>1.3</velocity>
          </limit>
          <dynamics>
            <damping>0.2</damping>
            <friction>0</friction>
            <spring_reference>0</spring_reference>
            <spring_stiffness>0</spring_stiffness>
          </dynamics>
          <use_parent_model_frame>1</use_parent_model_frame>
        </axis>
        <physics>
          <ode>
            <implicit_spring_damper>0</implicit_spring_damper>
            <cfm_damping>0</cfm_damping>
            <limit>
              <cfm>0</cfm>
              <erp>0.2</erp>
            </limit>
          </ode>
        </physics>
      </joint>
      <link name='r_wrist_center'>
        <pose frame=''>-0.01815 -0.183978 0.843446 0 -0 0</pose>
        <inertial>
          <pose frame=''>0 0 0 0 -0 0</pose>
          <mass>0.05</mass>
          <inertia>
            <ixx>0.0001</ixx>
            <ixy>0</ixy>
            <ixz>0</ixz>
            <iyy>0.0001</iyy>
            <iyz>0</iyz>
            <izz>0.0001</izz>
          </inertia>
        </inertial>
        <gravity>1</gravity>
        <velocity_decay/>
        <self_collide>0</self_collide>
        <enable_wind>0</enable_wind>
        <kinematic>0</kinematic>
      </link>
      <joint name='r_wrist_p_joint' type='revolute'>
        <child>r_wrist_center</child>
        <parent>r_forearm_link</parent>
        <axis>
          <xyz>0 1 0</xyz>
          <limit>
            <lower>-0.087</lower>
            <upper>0.087</upper>
            <effort>10</effort>
            <velocity>0.9</velocity>
          </limit>
          <dynamics>
            <damping>0.2</damping>
            <friction>0</friction>
            <spring_reference>0</spring_reference>
            <spring_stiffness>0</spring_stiffness>
          </dynamics>
          <use_parent_model_frame>1</use_parent_model_frame>
        </axis>
        <physics>
          <ode>
            <implicit_spring_damper>0</implicit_spring_damper>
            <cfm_damping>0</cfm_damping>
            <limit>
              <cfm>0</cfm>
              <erp>0.2</erp>
            </limit>
          </ode>
        </physics>
      </joint>
      <link name='r_hand_link'>
        <pose frame=''>-0.01815 -0.183978 0.843446 0 -0 0</pose>
        <inertial>
          <pose frame=''>0 0 -0.0875 0 -0 0</pose>
          <mass>0.183</mass>
          <inertia>
            <ixx>0.000601</ixx>
            <ixy>0</ixy>
            <ixz>0</ixz>
            <iyy>0.00055</iyy>
            <iyz>0</iyz>
            <izz>0.000102</izz>
          </inertia>
        </inertial>
        <collision name='r_hand_link_collision'>
          <pose frame=''>0 0 -0.093 0.7 -0 0</pose>
          <geometry>
            <box>
              <size>0.036 0.07 0.03</size>
            </box>
          </geometry>
          <surface>
            <contact>
              <ode/>
            </contact>
            <friction>
              <ode>
                <mu>0.9</mu>
                <mu2>0.9</mu2>
              </ode>
              <torsional>
                <ode/>
              </torsional>
            </friction>
            <bounce/>
          </surface>
          <max_contacts>10</max_contacts>
        </collision>
        <collision name='r_hand_link_collision_1'>
          <pose frame=''>0 -0.007 -0.055 -0.1 0 0</pose>
          <geometry>
            <box>
              <size>0.036 0.05 0.07</size>
            </box>
          </geometry>
          <surface>
            <contact>
              <ode/>
            </contact>
            <friction>
              <ode>
                <mu>0.9</mu>
                <mu2>0.9</mu2>
              </ode>
              <torsional>
                <ode/>
              </torsional>
            </friction>
            <bounce/>
          </surface>
          <max_contacts>10</max_contacts>
        </collision>
        <visual name='r_hand_link_visual'>
          <pose frame=''>0 0 0 0 -0 0</pose>
          <geometry>
            <mesh>
              <scale>1 1 1</scale>
              <uri>/home/ubuntu18/ros/melodic/src/seed_r7_ros_pkg/seed_r7_description/meshes/trx_s/RARM_LINK7_mesh.dae</uri>
            </mesh>
          </geometry>
          <material>
            <script>
              <uri>__default__</uri>
              <name>__default__</name>
            </script>
          </material>
        </visual>
        <gravity>1</gravity>
        <velocity_decay/>
        <self_collide>0</self_collide>
        <enable_wind>0</enable_wind>
        <kinematic>0</kinematic>
      </link>
      <joint name='r_wrist_r_joint' type='revolute'>
        <child>r_hand_link</child>
        <parent>r_wrist_center</parent>
        <axis>
          <xyz>1 0 0</xyz>
          <limit>
            <lower>-0.436</lower>
            <upper>1.484</upper>
            <effort>10</effort>
            <velocity>2.1</velocity>
          </limit>
          <dynamics>
            <damping>0.2</damping>
            <friction>0</friction>
            <spring_reference>0</spring_reference>
            <spring_stiffness>0</spring_stiffness>
          </dynamics>
          <use_parent_model_frame>1</use_parent_model_frame>
        </axis>
        <physics>
          <ode>
            <implicit_spring_damper>0</implicit_spring_damper>
            <cfm_damping>0</cfm_damping>
            <limit>
              <cfm>0</cfm>
              <erp>0.2</erp>
            </limit>
          </ode>
        </physics>
      </joint>
      <link name='r_indexbase_link'>
        <pose frame=''>-0.01815 -0.196978 0.728446 0 -0 0</pose>
        <inertial>
          <pose frame=''>0 0.042408 -0.037196 0 -0 0</pose>
          <mass>0.3</mass>
          <inertia>
            <ixx>0.00230024</ixx>
            <ixy>0</ixy>
            <ixz>0</ixz>
            <iyy>0.00034078</iyy>
            <iyz>7.64367e-05</iyz>
            <izz>0.000459461</izz>
          </inertia>
        </inertial>
        <collision name='r_indexbase_link_collision'>
          <pose frame=''>0.015 0.013494 -0.021422 -0.85 0 0</pose>
          <geometry>
            <box>
              <size>0.01 0.061 0.016</size>
            </box>
          </geometry>
          <surface>
            <contact>
              <ode/>
            </contact>
            <friction>
              <ode>
                <mu>0.9</mu>
                <mu2>0.9</mu2>
              </ode>
              <torsional>
                <ode/>
              </torsional>
            </friction>
            <bounce/>
          </surface>
          <max_contacts>10</max_contacts>
        </collision>
        <collision name='r_indexbase_link_collision_1'>
          <pose frame=''>-0.015 0.013494 -0.021422 -0.85 0 0</pose>
          <geometry>
            <box>
              <size>0.01 0.061 0.016</size>
            </box>
          </geometry>
          <surface>
            <contact>
              <ode/>
            </contact>
            <friction>
              <ode>
                <mu>0.9</mu>
                <mu2>0.9</mu2>
              </ode>
              <torsional>
                <ode/>
              </torsional>
            </friction>
            <bounce/>
          </surface>
          <max_contacts>10</max_contacts>
        </collision>
        <collision name='r_indexbase_link_fixed_joint_lump__r_indexmid_link_collision_2'>
          <pose frame=''>0.015 0.042754 -0.042615 -0.3 0 0</pose>
          <geometry>
            <box>
              <size>0.01 0.03 0.016</size>
            </box>
          </geometry>
          <surface>
            <contact>
              <ode/>
            </contact>
            <friction>
              <ode>
                <mu>0.9</mu>
                <mu2>0.9</mu2>
              </ode>
              <torsional>
                <ode/>
              </torsional>
            </friction>
            <bounce/>
          </surface>
          <max_contacts>10</max_contacts>
        </collision>
        <collision name='r_indexbase_link_fixed_joint_lump__r_indexmid_link_collision_3'>
          <pose frame=''>-0.015 0.042754 -0.042615 -0.3 0 0</pose>
          <geometry>
            <box>
              <size>0.01 0.03 0.016</size>
            </box>
          </geometry>
          <surface>
            <contact>
              <ode/>
            </contact>
            <friction>
              <ode>
                <mu>0.9</mu>
                <mu2>0.9</mu2>
              </ode>
              <torsional>
                <ode/>
              </torsional>
            </friction>
            <bounce/>
          </surface>
          <max_contacts>10</max_contacts>
        </collision>
        <collision name='r_indexbase_link_fixed_joint_lump__r_indexend_link_collision_4'>
          <pose frame=''>0.015 0.06347 -0.043972 0 -0 0</pose>
          <geometry>
            <box>
              <size>0.01 0.028 0.016</size>
            </box>
          </geometry>
          <surface>
            <contact>
              <ode/>
            </contact>
            <friction>
              <ode>
                <mu>0.9</mu>
                <mu2>0.9</mu2>
              </ode>
              <torsional>
                <ode/>
              </torsional>
            </friction>
            <bounce/>
          </surface>
          <max_contacts>10</max_contacts>
        </collision>
        <collision name='r_indexbase_link_fixed_joint_lump__r_indexend_link_collision_5'>
          <pose frame=''>-0.015 0.06347 -0.043972 0 -0 0</pose>
          <geometry>
            <box>
              <size>0.01 0.028 0.016</size>
            </box>
          </geometry>
          <surface>
            <contact>
              <ode/>
            </contact>
            <friction>
              <ode>
                <mu>0.9</mu>
                <mu2>0.9</mu2>
              </ode>
              <torsional>
                <ode/>
              </torsional>
            </friction>
            <bounce/>
          </surface>
          <max_contacts>10</max_contacts>
        </collision>
        <visual name='r_indexbase_link_visual'>
          <pose frame=''>0 0.013 0.115 0 -0 0</pose>
          <geometry>
            <mesh>
              <scale>1 1 1</scale>
              <uri>/home/ubuntu18/ros/melodic/src/seed_r7_ros_pkg/seed_r7_description/meshes/trx_s/RARM_INDEX_LINK1_mesh.dae</uri>
            </mesh>
          </geometry>
          <material>
            <script>
              <uri>__default__</uri>
              <name>__default__</name>
            </script>
          </material>
        </visual>
        <visual name='r_indexbase_link_fixed_joint_lump__r_indexmid_link_visual_1'>
          <pose frame=''>0 0.013 0.115 0 -0 0</pose>
          <geometry>
            <mesh>
              <scale>1 1 1</scale>
              <uri>/home/ubuntu18/ros/melodic/src/seed_r7_ros_pkg/seed_r7_description/meshes/trx_s/RARM_INDEX_LINK2_mesh.dae</uri>
            </mesh>
          </geometry>
          <material>
            <script>
              <uri>__default__</uri>
              <name>__default__</name>
            </script>
          </material>
        </visual>
        <visual name='r_indexbase_link_fixed_joint_lump__r_indexend_link_visual_2'>
          <pose frame=''>0 0.013 0.115 0 -0 0</pose>
          <geometry>
            <mesh>
              <scale>1 1 1</scale>
              <uri>/home/ubuntu18/ros/melodic/src/seed_r7_ros_pkg/seed_r7_description/meshes/trx_s/RARM_INDEX_LINK3_mesh.dae</uri>
            </mesh>
          </geometry>
          <material>
            <script>
              <uri>__default__</uri>
              <name>__default__</name>
            </script>
          </material>
        </visual>
        <velocity_decay/>
        <velocity_decay/>
        <gravity>1</gravity>
        <velocity_decay/>
        <self_collide>0</self_collide>
        <enable_wind>0</enable_wind>
        <kinematic>0</kinematic>
      </link>
      <joint name='r_indexbase_joint' type='revolute'>
        <child>r_indexbase_link</child>
        <parent>r_hand_link</parent>
        <axis>
          <xyz>1 0 0</xyz>
          <limit>
            <lower>-1e+16</lower>
            <upper>1e+16</upper>
          </limit>
          <dynamics>
            <spring_reference>0</spring_reference>
            <spring_stiffness>0</spring_stiffness>
          </dynamics>
          <use_parent_model_frame>1</use_parent_model_frame>
        </axis>
      </joint>
      <link name='r_thumb_link'>
        <pose frame=''>-0.01815 -0.161623 0.763801 0 -0 0</pose>
        <inertial>
          <pose frame=''>0 0.05 -0.06 0 -0 0</pose>
          <mass>0.1</mass>
          <inertia>
            <ixx>0.001</ixx>
            <ixy>0</ixy>
            <ixz>0</ixz>
            <iyy>0.0001</iyy>
            <iyz>0</iyz>
            <izz>0.0001</izz>
          </inertia>
        </inertial>
        <collision name='r_thumb_link_collision'>
          <pose frame=''>0 0.019645 -0.010355 0.63 -0 0</pose>
          <geometry>
            <box>
              <size>0.012 0.008 0.05</size>
            </box>
          </geometry>
          <surface>
            <contact>
              <ode/>
            </contact>
            <friction>
              <ode>
                <mu>0.9</mu>
                <mu2>0.9</mu2>
              </ode>
              <torsional>
                <ode/>
              </torsional>
            </friction>
            <bounce/>
          </surface>
          <max_contacts>10</max_contacts>
        </collision>
        <collision name='r_thumb_link_collision_1'>
          <pose frame=''>0 0.035645 -0.050355 0.1 -0 0</pose>
          <geometry>
            <box>
              <size>0.012 0.008 0.05</size>
            </box>
          </geometry>
          <surface>
            <contact>
              <ode/>
            </contact>
            <friction>
              <ode>
                <mu>0.9</mu>
                <mu2>0.9</mu2>
              </ode>
              <torsional>
                <ode/>
              </torsional>
            </friction>
            <bounce/>
          </surface>
          <max_contacts>10</max_contacts>
        </collision>
        <visual name='r_thumb_link_visual'>
          <pose frame=''>0 -0.022355 0.079645 0 -0 0</pose>
          <geometry>
            <mesh>
              <scale>1 1 1</scale>
              <uri>/home/ubuntu18/ros/melodic/src/seed_r7_ros_pkg/seed_r7_description/meshes/trx_s/RARM_THUMB_LINK_mesh.dae</uri>
            </mesh>
          </geometry>
          <material>
            <script>
              <uri>__default__</uri>
              <name>__default__</name>
            </script>
          </material>
        </visual>
        <gravity>1</gravity>
        <velocity_decay/>
        <self_collide>0</self_collide>
        <enable_wind>0</enable_wind>
        <kinematic>0</kinematic>
      </link>
      <joint name='r_thumb_joint' type='revolute'>
        <child>r_thumb_link</child>
        <parent>r_hand_link</parent>
        <axis>
          <xyz>1 0 0</xyz>
          <limit>
            <lower>-1</lower>
            <upper>1</upper>
            <effort>50</effort>
            <velocity>0.5</velocity>
          </limit>
          <dynamics>
            <damping>0.2</damping>
            <friction>0</friction>
            <spring_reference>0</spring_reference>
            <spring_stiffness>0</spring_stiffness>
          </dynamics>
          <use_parent_model_frame>1</use_parent_model_frame>
        </axis>
        <physics>
          <ode>
            <implicit_spring_damper>0</implicit_spring_damper>
            <cfm_damping>0</cfm_damping>
            <limit>
              <cfm>0</cfm>
              <erp>0.2</erp>
            </limit>
          </ode>
        </physics>
      </joint>
      <link name='leg_thigh_link_dummy'>
        <pose frame=''>0.03182 0 0.58318 0 -0 0</pose>
        <inertial>
          <pose frame=''>-0.04 0 0.14 0 -0 0</pose>
          <mass>0.4</mass>
          <inertia>
            <ixx>0.001</ixx>
            <ixy>0</ixy>
            <ixz>0</ixz>
            <iyy>0.001</iyy>
            <iyz>0</iyz>
            <izz>0.001</izz>
          </inertia>
        </inertial>
        <collision name='leg_thigh_link_dummy_collision'>
          <pose frame=''>0 0 0.125 0 -0 0</pose>
          <geometry>
            <box>
              <size>0.04 0.09 0.286</size>
            </box>
          </geometry>
          <max_contacts>10</max_contacts>
          <surface>
            <contact>
              <ode/>
            </contact>
            <bounce/>
            <friction>
              <torsional>
                <ode/>
              </torsional>
              <ode/>
            </friction>
          </surface>
        </collision>
        <visual name='leg_thigh_link_dummy_visual'>
          <pose frame=''>0 0 0.25 0 -0 0</pose>
          <geometry>
            <mesh>
              <scale>1 1 1</scale>
              <uri>/home/ubuntu18/ros/melodic/src/seed_r7_ros_pkg/seed_r7_description/meshes/typeC_lifter/lifter_bone_dummy.dae</uri>
            </mesh>
          </geometry>
        </visual>
        <self_collide>0</self_collide>
        <enable_wind>0</enable_wind>
        <kinematic>0</kinematic>
      </link>
      <joint name='knee_joint_dummy' type='revolute'>
        <child>leg_thigh_link_dummy</child>
        <parent>leg_knee_link</parent>
        <axis>
          <xyz>0 1 0</xyz>
          <limit>
            <lower>-1e+16</lower>
            <upper>1e+16</upper>
          </limit>
          <dynamics>
            <spring_reference>0</spring_reference>
            <spring_stiffness>0</spring_stiffness>
          </dynamics>
          <use_parent_model_frame>1</use_parent_model_frame>
        </axis>
      </joint>
      <link name='leg_shank_link_dummy'>
        <pose frame=''>0.03182 0 0.27682 0 -0 0</pose>
        <inertial>
          <pose frame=''>-0.04 0 0.14 0 -0 0</pose>
          <mass>0.4</mass>
          <inertia>
            <ixx>0.001</ixx>
            <ixy>0</ixy>
            <ixz>0</ixz>
            <iyy>0.001</iyy>
            <iyz>0</iyz>
            <izz>0.001</izz>
          </inertia>
        </inertial>
        <collision name='leg_shank_link_dummy_collision'>
          <pose frame=''>0 0 0.125 0 -0 0</pose>
          <geometry>
            <box>
              <size>0.04 0.09 0.286</size>
            </box>
          </geometry>
          <max_contacts>10</max_contacts>
          <surface>
            <contact>
              <ode/>
            </contact>
            <bounce/>
            <friction>
              <torsional>
                <ode/>
              </torsional>
              <ode/>
            </friction>
          </surface>
        </collision>
        <visual name='leg_shank_link_dummy_visual'>
          <pose frame=''>0 0 0.25 0 -0 0</pose>
          <geometry>
            <mesh>
              <scale>1 1 1</scale>
              <uri>/home/ubuntu18/ros/melodic/src/seed_r7_ros_pkg/seed_r7_description/meshes/typeC_lifter/lifter_bone_dummy.dae</uri>
            </mesh>
          </geometry>
        </visual>
        <self_collide>0</self_collide>
        <enable_wind>0</enable_wind>
        <kinematic>0</kinematic>
      </link>
      <joint name='ankle_joint_dummy' type='revolute'>
        <child>leg_shank_link_dummy</child>
        <parent>base_link</parent>
        <axis>
          <xyz>0 -1 0</xyz>
          <limit>
            <lower>-1e+16</lower>
            <upper>1e+16</upper>
          </limit>
          <dynamics>
            <spring_reference>0</spring_reference>
            <spring_stiffness>0</spring_stiffness>
          </dynamics>
          <use_parent_model_frame>1</use_parent_model_frame>
        </axis>
      </joint>
      <plugin name='gazebo_ros_control' filename='libgazebo_ros_control.so'>
        <robotNamespace>/</robotNamespace>
        <robotSimType>gazebo_ros_control/DefaultRobotHWSim</robotSimType>
        <legacyModeNS>1</legacyModeNS>
      </plugin>
      <plugin name='cmd_vel_controller' filename='libgazebo_ros_planar_force_move.so'>
        <commandTopic>cmd_vel</commandTopic>
        <odometryTopic>odom</odometryTopic>
        <odometryFrame>odom</odometryFrame>
        <odometryRate>40.0</odometryRate>
        <robotBaseFrame>base_link</robotBaseFrame>
        <useForceFeedback>1</useForceFeedback>
        <appliedForceLink>base_link</appliedForceLink>
        <forceGainX>24000</forceGainX>
        <forceGainY>24000</forceGainY>
        <forceGainRot>6000</forceGainRot>
        <robotNamespace>/</robotNamespace>
      </plugin>
      <static>0</static>
      <plugin name='mimic_updater' filename='libmimic_plugin.so'>
        <mimic D='1' I='0.01' P='1000' command_max='50' command_min='-50' i_max='0' i_min='0' joint='knee_joint' multiplier='-1.0' offset='0.0' velocity='1'>knee_joint_mimic</mimic>
        <mimic D='1' I='0.01' P='1000' command_max='50' command_min='-50' i_max='0' i_min='0' joint='ankle_joint' multiplier='-1.0' offset='0.0' velocity='1'>ankle_joint_mimic</mimic>
        <mimic D='1' I='0.01' P='100' command_max='50' command_min='-50' i_max='0' i_min='0' joint='knee_joint' multiplier='-1.0' offset='0.0' velocity='1'>knee_joint_dummy</mimic>
        <mimic D='1' I='0.01' P='100' command_max='50' command_min='-50' i_max='0' i_min='0' joint='ankle_joint' multiplier='1.0' offset='0.0' velocity='1'>ankle_joint_dummy</mimic>
        <mimic D='1' I='0.0' P='10' command_max='50' command_min='-50' i_max='0' i_min='0' joint='l_thumb_joint' multiplier='-1.0' offset='0.0' velocity='1'>l_indexbase_joint</mimic>
        <mimic D='1' I='0.0' P='10' command_max='50' command_min='-50' i_max='0' i_min='0' joint='r_thumb_joint' multiplier='-1.0' offset='0.0' velocity='1'>r_indexbase_joint</mimic>
        <robotNamespace>/</robotNamespace>
      </plugin>
      <pose frame=''>0 0 0 0 -0 0</pose>
    </model>
    <model name='train_yanenasi'>
      <link name='link_3'>
        <inertial>
          <mass>1</mass>
          <inertia>
            <ixx>0.166667</ixx>
            <ixy>0</ixy>
            <ixz>0</ixz>
            <iyy>0.166667</iyy>
            <iyz>0</iyz>
            <izz>0.166667</izz>
          </inertia>
          <pose frame=''>0 0 0 0 -0 0</pose>
        </inertial>
        <pose frame=''>0 0 0 0 -0 0</pose>
        <gravity>1</gravity>
        <self_collide>1</self_collide>
        <kinematic>0</kinematic>
        <enable_wind>0</enable_wind>
        <visual name='visual'>
          <pose frame=''>0 0 0 0 -0 0</pose>
          <geometry>
            <mesh>
              <uri>/home/ubuntu18/ros/melodic/src/seed_r7_ros_pkg/seed_r7_description/meshes/train/train_yanenasi.dae</uri>
              <scale>1 1 1</scale>
            </mesh>
          </geometry>
          <material>
            <lighting>1</lighting>
            <script>
              <uri>file://media/materials/scripts/gazebo.material</uri>
              <name>Gazebo/Grey</name>
            </script>
            <shader type='pixel'>
              <normal_map>__default__</normal_map>
            </shader>
            <ambient>0.3 0.3 0.3 1</ambient>
            <diffuse>0.7 0.7 0.7 1</diffuse>
            <specular>0.01 0.01 0.01 1</specular>
            <emissive>0 0 0 1</emissive>
          </material>
          <transparency>0</transparency>
          <cast_shadows>1</cast_shadows>
        </visual>
        <collision name='collision'>
          <laser_retro>0</laser_retro>
          <max_contacts>10</max_contacts>
          <pose frame=''>0 0 0 0 -0 0</pose>
          <geometry>
            <mesh>
              <uri>/home/ubuntu18/ros/melodic/src/seed_r7_ros_pkg/seed_r7_description/meshes/train/train_yanenasi.dae</uri>
              <scale>1 1 1</scale>
            </mesh>
          </geometry>
          <surface>
            <friction>
              <ode>
                <mu>1</mu>
                <mu2>1</mu2>
                <fdir1>0 0 0</fdir1>
                <slip1>0</slip1>
                <slip2>0</slip2>
              </ode>
              <torsional>
                <coefficient>1</coefficient>
                <patch_radius>0</patch_radius>
                <surface_radius>0</surface_radius>
                <use_patch_radius>1</use_patch_radius>
                <ode>
                  <slip>0</slip>
                </ode>
              </torsional>
            </friction>
            <bounce>
              <restitution_coefficient>0</restitution_coefficient>
              <threshold>1e+06</threshold>
            </bounce>
            <contact>
              <collide_without_contact>0</collide_without_contact>
              <collide_without_contact_bitmask>1</collide_without_contact_bitmask>
              <collide_bitmask>1</collide_bitmask>
              <ode>
                <soft_cfm>0</soft_cfm>
                <soft_erp>0.2</soft_erp>
                <kp>1e+13</kp>
                <kd>1</kd>
                <max_vel>0.01</max_vel>
                <min_depth>0</min_depth>
              </ode>
              <bullet>
                <split_impulse>1</split_impulse>
                <split_impulse_penetration_threshold>-0.01</split_impulse_penetration_threshold>
                <soft_cfm>0</soft_cfm>
                <soft_erp>0.2</soft_erp>
                <kp>1e+13</kp>
                <kd>1</kd>
              </bullet>
            </contact>
          </surface>
        </collision>
      </link>
      <static>0</static>
      <allow_auto_disable>1</allow_auto_disable>
      <pose frame=''>-0.703623 1.70436 0 0 -0 0</pose>
    </model>
    <state world_name='default'>
      <sim_time>0 0</sim_time>
      <real_time>0 0</real_time>
      <wall_time>1615341594 685571138</wall_time>
      <iterations>0</iterations>
      <model name='ground_plane'>
        <pose frame=''>0 0 0 0 -0 0</pose>
        <scale>1 1 1</scale>
        <link name='link'>
          <pose frame=''>0 0 0 0 -0 0</pose>
          <velocity>0 0 0 0 -0 0</velocity>
          <acceleration>0 0 0 0 -0 0</acceleration>
          <wrench>0 0 0 0 -0 0</wrench>
        </link>
      </model>
      <model name='seed_r7'>
        <pose frame=''>0 0 1.5 -0 3e-05 -3e-05</pose>
        <scale>1 1 1</scale>
        <link name='base_link'>
          <pose frame=''>0 0 1.5 -0 3e-05 -3e-05</pose>
          <velocity>1.5e-05 -1e-06 -0.004493 3.2e-05 0.014899 -3e-06</velocity>
          <acceleration>1.84006 -0.004397 -4.49617 -3.11241 0.777621 3.13989</acceleration>
          <wrench>152.441 -0.364293 -372.49 0 -0 0</wrench>
        </link>
        <link name='body_link'>
          <pose frame=''>1.1e-05 -1e-06 2.56529 1.2e-05 2e-05 -9e-06</pose>
          <velocity>0.004337 -0.000459 -0.000404 -0.000359 0.010553 -0.001236</velocity>
          <acceleration>0.573966 -0.28771 -0.360207 -0.701514 0.962076 -0.632742</acceleration>
          <wrench>6.05591 -3.03562 -3.80055 0 -0 0</wrench>
        </link>
        <link name='head_base_link'>
          <pose frame=''>2e-05 -1e-05 3.02328 3.7e-05 3.4e-05 -4e-06</pose>
          <velocity>0.008711 -0.000603 -0.000161 0.003205 0.007138 -0.001659</velocity>
          <acceleration>0.265088 -0.455496 -0.124759 -2.88324 0.839434 -1.0114</acceleration>
          <wrench>0.026509 -0.04555 -0.012476 0 -0 0</wrench>
        </link>
        <link name='head_link'>
          <pose frame=''>2.1e-05 -9e-06 3.02328 3.1e-05 2.8e-05 -4e-06</pose>
          <velocity>0.008752 -0.000571 -0.000226 0.002183 0.008433 -0.001549</velocity>
          <acceleration>0.038745 -0.613016 -0.148362 -0.563325 0.769489 2.22803</acceleration>
          <wrench>0.037737 -0.597078 -0.144504 0 -0 0</wrench>
        </link>
        <link name='hip_center'>
          <pose frame=''>1.2e-05 -0 2.56522 0 1.6e-05 -9e-06</pose>
          <velocity>0.004282 -0.000424 0.000893 -0.000773 0.008334 -0.001282</velocity>
          <acceleration>0.314781 -0.439856 0.955704 -1.07297 -1.2522 -0.546722</acceleration>
          <wrench>0.031478 -0.043986 0.09557 0 -0 0</wrench>
        </link>
        <link name='hip_sphere_link'>
          <pose frame=''>1.1e-05 -3e-06 2.42995 1e-06 -1e-05 -1e-05</pose>
          <velocity>0.002223 -0.000544 -0.003357 0.000284 0.01535 -0.001133</velocity>
          <acceleration>-0.138926 -0.44493 -3.35927 0.169094 -1.47009 -0.779166</acceleration>
          <wrench>-0.17463 -0.559277 -4.2226 0 -0 0</wrench>
        </link>
        <link name='l_elbow_link'>
          <pose frame=''>0.016796 0.183948 2.60871 -0.000106 0.00028 -3.4e-05</pose>
          <velocity>0.004363 -0.002231 -0.00041 -0.005415 0.0136 7.9e-05</velocity>
          <acceleration>0.053902 -0.440194 -0.255241 0.188129 1.36994 0.095905</acceleration>
          <wrench>0.038324 -0.312978 -0.181477 0 -0 0</wrench>
        </link>
        <link name='l_forearm_link'>
          <pose frame=''>-0.018223 0.183941 2.53871 -0.000111 0.000268 -2.7e-05</pose>
          <velocity>0.003432 -0.002577 0.000115 -0.004571 0.012981 0.000451</velocity>
          <acceleration>-0.018157 -0.333199 -0.204256 0.971967 0.94909 0.177033</acceleration>
          <wrench>-0.002397 -0.043982 -0.026962 0 -0 0</wrench>
        </link>
        <link name='l_hand_link'>
          <pose frame=''>-0.018277 0.183918 2.3432 -0.00014 0.00039 -2.3e-05</pose>
          <velocity>0.000881 -0.003486 0.000209 -0.00079 0.010339 0.002356</velocity>
          <acceleration>-0.084097 0.074087 -0.103824 -2.78917 -0.631817 1.03964</acceleration>
          <wrench>-0.01539 0.013558 -0.019 0 -0 0</wrench>
        </link>
        <link name='l_indexbase_link'>
          <pose frame=''>-0.018321 0.196902 2.2282 0.007403 0.00039 -2.3e-05</pose>
          <velocity>-0.00032 -0.003583 0.000189 -0.009501 0.010386 0.002046</velocity>
          <acceleration>-0.011411 1.56399 -1.63188 -0.467932 -0.582784 0.927536</acceleration>
          <wrench>-0.003423 0.469198 -0.489563 0 -0 0</wrench>
        </link>
        <link name='l_shoulder_center'>
          <pose frame=''>-0.01812 0.193974 2.89822 -0.000103 0.000292 -5.1e-05</pose>
          <velocity>0.007978 -0.000427 -6.6e-05 -0.006205 0.012571 0.000356</velocity>
          <acceleration>0.566352 -0.320071 -0.261093 2.61265 1.21811 -2.94157</acceleration>
          <wrench>0.421366 -0.238133 -0.194253 0 -0 0</wrench>
        </link>
        <link name='l_shoulder_link'>
          <pose frame=''>-0.018131 0.134194 2.87018 -9.4e-05 0.000285 -5.4e-05</pose>
          <velocity>0.00765 -0.000386 -8.7e-05 -0.000629 0.012564 -0.000839</velocity>
          <acceleration>0.712218 -0.252321 -0.28202 2.32637 1.0477 2.82753</acceleration>
          <wrench>0.172357 -0.061062 -0.068249 0 -0 0</wrench>
        </link>
        <link name='l_thumb_link'>
          <pose frame=''>-0.018308 0.161552 2.26356 -0.000123 0.000391 -2.5e-05</pose>
          <velocity>0.000114 -0.003557 0.000202 -0.000209 0.010749 0.001274</velocity>
          <acceleration>-0.010488 0.236831 -0.372271 -2.9883 -0.381107 0.587832</acceleration>
          <wrench>-0.001049 0.023683 -0.037227 0 -0 0</wrench>
        </link>
        <link name='l_upperarm_link'>
          <pose frame=''>-0.018157 0.183965 2.77122 -0.000102 0.000284 -3.4e-05</pose>
          <velocity>0.006399 -0.001227 1.3e-05 -0.005879 0.012368 9.6e-05</velocity>
          <acceleration>0.322757 -0.382867 -0.25275 2.90286 1.36779 -3.02815</acceleration>
          <wrench>0.185262 -0.219766 -0.145079 0 -0 0</wrench>
        </link>
        <link name='l_wrist_center'>
          <pose frame=''>-0.018277 0.183918 2.3432 -0.000109 0.000388 -2.5e-05</pose>
          <velocity>0.000848 -0.003523 0.000227 -0.000827 0.009409 0.00158</velocity>
          <acceleration>-0.162013 -0.266711 -0.084552 -1.80955 -1.3046 0.663219</acceleration>
          <wrench>-0.008101 -0.013336 -0.004228 0 -0 0</wrench>
        </link>
        <link name='leg_base_link'>
          <pose frame=''>1.1e-05 -3e-06 2.36497 3e-06 -6e-06 -2.7e-05</pose>
          <velocity>0.001071 -0.000508 -0.003684 0.000801 0.017862 -0.001124</velocity>
          <acceleration>-1.68184 -0.400503 -4.03994 0.612006 -0.832282 -0.866036</acceleration>
          <wrench>-16.6553 -3.9662 -40.0077 0 -0 0</wrench>
        </link>
        <link name='leg_knee_link'>
          <pose frame=''>1.4e-05 -1e-06 1.99498 2e-06 -2.8e-05 -2.9e-05</pose>
          <velocity>0.006946 -0.000158 -0.003883 0.000613 -0.023297 7.9e-05</velocity>
          <acceleration>7.74514 -0.156129 -3.80754 0.43988 -0.022883 0.07856</acceleration>
          <wrench>16.0076 -0.322686 -7.86939 0 -0 0</wrench>
        </link>
        <link name='leg_shank_link'>
          <pose frame=''>7e-06 -0 1.74499 2e-06 1.9e-05 -2.9e-05</pose>
          <velocity>0.003632 -7.1e-05 -0.00411 0.000454 0.013463 0.000113</velocity>
          <acceleration>5.89562 -0.103844 -4.91293 -2.78162 0.360628 -3.04599</acceleration>
          <wrench>12.185 -0.214623 -10.154 0 -0 0</wrench>
        </link>
        <link name='leg_shank_link_dummy'>
          <pose frame=''>0.031828 -1e-06 1.77682 -0 -0.000378 -3e-05</pose>
          <velocity>0.004116 -9e-06 -0.004963 3.5e-05 -0.053897 1.6e-05</velocity>
          <acceleration>-0.424545 -0.013521 -6.28125 0.031539 -1.16467 0.008201</acceleration>
          <wrench>-0.169818 -0.005408 -2.5125 0 -0 0</wrench>
        </link>
        <link name='leg_thigh_link'>
          <pose frame=''>1e-05 -1e-06 2.11497 2e-06 5.8e-05 -2.5e-05</pose>
          <velocity>0.004151 -0.000318 -0.003615 0.000758 -0.013695 -0.001099</velocity>
          <acceleration>1.6055 -0.279807 -5.03575 0.591434 1.07011 -0.853309</acceleration>
          <wrench>4.21157 -0.733993 -13.2098 0 -0 0</wrench>
        </link>
        <link name='leg_thigh_link_dummy'>
          <pose frame=''>0.031831 -2e-06 2.08318 1e-06 -0.000156 -3e-05</pose>
          <velocity>0.004902 -0.000155 -0.003594 0.000242 -0.15541 9.9e-05</velocity>
          <acceleration>0.117859 -0.181106 -6.68797 0.254306 0.182308 0.088918</acceleration>
          <wrench>0.047144 -0.072442 -2.67519 0 -0 0</wrench>
        </link>
        <link name='neck_link'>
          <pose frame=''>1.8e-05 -7e-06 2.91879 2.7e-05 3e-05 -4e-06</pose>
          <velocity>0.007918 -0.000432 -0.000348 0.001156 0.008062 -0.001352</velocity>
          <acceleration>0.410492 -0.361852 -0.306391 -2.09478 -1.15335 2.40468</acceleration>
          <wrench>0.139978 -0.123392 -0.104479 0 -0 0</wrench>
        </link>
        <link name='r_elbow_link'>
          <pose frame=''>0.016801 -0.183887 2.60871 0.000363 0.000258 5.8e-05</pose>
          <velocity>0.003366 0.011882 0.000617 0.028923 0.015963 0.002182</velocity>
          <acceleration>0.271448 5.76764 0.850001 -3.01085 -0.215082 1.42436</acceleration>
          <wrench>0.193 4.10079 0.604351 0 -0 0</wrench>
        </link>
        <link name='r_forearm_link'>
          <pose frame=''>-0.018218 -0.183862 2.53872 0.000359 0.000267 3.6e-05</pose>
          <velocity>0.002284 0.013537 0.001354 0.014416 0.015425 0.00271</velocity>
          <acceleration>0.318504 5.63542 1.06034 -1.02096 -0.344269 1.6682</acceleration>
          <wrench>0.042042 0.743875 0.139965 0 -0 0</wrench>
        </link>
        <link name='r_hand_link'>
          <pose frame=''>-0.018271 -0.183789 2.3432 0.000296 0.000224 6.5e-05</pose>
          <velocity>-0.000723 0.017019 0.001676 -0.04381 0.021328 0.001607</velocity>
          <acceleration>0.560011 2.32239 1.44202 -0.874266 -1.1626 -2.48342</acceleration>
          <wrench>0.102482 0.424997 0.26389 0 -0 0</wrench>
        </link>
        <link name='r_indexbase_link'>
          <pose frame=''>-0.018296 -0.196755 2.2282 -0.007179 0.000223 6e-05</pose>
          <velocity>-0.003142 0.01205 0.002184 0.016021 0.021395 0.001845</velocity>
          <acceleration>0.667975 -0.658673 -0.146441 -2.7084 -1.22761 -2.35514</acceleration>
          <wrench>0.200392 -0.197602 -0.043932 0 -0 0</wrench>
        </link>
        <link name='r_shoulder_center'>
          <pose frame=''>-0.018128 -0.193977 2.89822 0.000383 0.00027 4.4e-05</pose>
          <velocity>0.007739 0.000973 0.000606 0.041282 0.014387 0.00313</velocity>
          <acceleration>0.452274 1.92224 0.743601 -0.121995 0.435771 2.9641</acceleration>
          <wrench>0.336492 1.43015 0.55324 0 -0 0</wrench>
        </link>
        <link name='r_shoulder_link'>
          <pose frame=''>-0.018134 -0.1342 2.87018 0.000294 0.000224 2.4e-05</pose>
          <velocity>0.007352 0.000426 0.000413 0.018249 0.015682 0.000242</velocity>
          <acceleration>0.553692 0.159622 0.077742 1.13867 1.01417 -0.31319</acceleration>
          <wrench>0.133993 0.038629 0.018814 0 -0 0</wrench>
        </link>
        <link name='r_thumb_link'>
          <pose frame=''>-0.01829 -0.161411 2.26357 0.000327 0.000216 4.9e-05</pose>
          <velocity>-0.002464 0.013525 0.000587 -0.040748 0.021707 0.002281</velocity>
          <acceleration>0.556325 0.313892 -1.55988 1.90874 -1.42895 -1.88758</acceleration>
          <wrench>0.055632 0.031389 -0.155988 0 -0 0</wrench>
        </link>
        <link name='r_upperarm_link'>
          <pose frame=''>-0.018158 -0.183945 2.77122 0.000366 0.000264 5.5e-05</pose>
          <velocity>0.005757 0.005415 0.001081 0.036343 0.014406 0.001692</velocity>
          <acceleration>0.329857 3.45539 0.811514 2.43268 0.526982 1.042</acceleration>
          <wrench>0.189338 1.98339 0.465809 0 -0 0</wrench>
        </link>
        <link name='r_wrist_center'>
          <pose frame=''>-0.01827 -0.183789 2.3432 0.00028 0.000247 5.3e-05</pose>
          <velocity>-0.000759 0.017645 0.001754 -0.060444 0.020205 0.002087</velocity>
          <acceleration>0.364773 6.43578 1.53312 -2.13159 -0.511527 -2.04565</acceleration>
          <wrench>0.018239 0.321789 0.076656 0 -0 0</wrench>
        </link>
      </model>
      <model name='train_yanenasi'>
        <pose frame=''>0 0 0 0 -0 0</pose>
        <scale>1 1 1</scale>
        <link name='link_3'>
          <pose frame=''>0 0 0 0 -0 0</pose>
          <velocity>0 0 0 0 -0 0</velocity>
          <acceleration>0 0 0 0 -0 0</acceleration>
          <wrench>0 0 0 0 -0 0</wrench>
        </link>
      </model>
      <light name='sun'>
        <pose frame=''>0 0 10 0 -0 0</pose>
      </light>
    </state>
  </world>
</sdf>
